2023-05-24--13-26 : starting to run unit tests from test_parser.log ... 
Page /reader/serp996/read/~0 is in dump at cache/reader/serp996/read/ ~0.html.
Page /reader/qwerty5677890/read/~0 is in dump at cache/reader/qwerty5677890/read/ ~0.html.
Successfully connected to C:/Users/user/PycharmProjects/livelib-bot/livelib/tests/data/sample/test_reader/main.db db.
Adding new Reader to DB: Reader93353251 at id = 355
Added new 573 entries to ReadBook for Reader 355 Reader93353251
Filling update_time of Reader Reader93353251 to 2023-05-24 13:26:25.621118
Delete read books for Reader 355 Reader93353251
Adding new Reader to DB: Reader18304517 at id = 356
Added new 573 entries to ReadBook for Reader 356 Reader18304517
Filling update_time of Reader Reader18304517 to 2023-05-24 13:26:27.279338
Delete read books for Reader 356 Reader18304517
Making request to /reader/qwertyuioop/read/~0
Random sleep.
Add site prefix to url
Starting new HTTP connection (1): www.livelib.ru:80
http://www.livelib.ru:80 "GET /reader/qwertyuioop/read/~0 HTTP/1.1" 302 138
Starting new HTTPS connection (1): www.livelib.ru:443
https://www.livelib.ru:443 "GET /reader/qwertyuioop/read/~0 HTTP/1.1" 404 None
Page at /reader/qwertyuioop/read/~0 is 404!
Making request to /reader/zverek_alyona/read/~0
Random sleep.
Add site prefix to url
Starting new HTTP connection (1): www.livelib.ru:80
http://www.livelib.ru:80 "GET /reader/zverek_alyona/read/~0 HTTP/1.1" 302 138
Starting new HTTPS connection (1): www.livelib.ru:443
https://www.livelib.ru:443 "GET /reader/zverek_alyona/read/~0 HTTP/1.1" 200 None
Adding new Reader to DB: Reader94195340 at id = 357
Filling update_time of Reader Reader94195340 to 2023-05-24 13:29:55.780074
Adding new Reader to DB: Reader11678508 at id = 358
Added new 573 entries to ReadBook for Reader 358 Reader11678508
Filling update_time of Reader Reader11678508 to 2023-05-24 13:29:57.370448
Delete read books for Reader 358 Reader11678508
Page /reader/Kasssiopei/read/~0 is in dump at C:/Users/user/PycharmProjects/livelib-bot/livelib/tests/data/sample/test_reader/get_read_books_from_page/cache/reader/kasssiopei/read/ ~0.html.
Page /reader/Kasssiopei/read/~0 is in dump at C:/Users/user/PycharmProjects/livelib-bot/livelib/tests/data/sample/test_reader/get_read_books_from_page/cache/reader/kasssiopei/read/ ~0.html.
Page /reader/Humming_Bird/read/~0 is in dump at C:/Users/user/PycharmProjects/livelib-bot/livelib/tests/data/sample/test_reader/get_read_books_from_web/cache/reader/humming_bird/read/ ~0.html.
Page /reader/Humming_Bird/read/~1 is in dump at C:/Users/user/PycharmProjects/livelib-bot/livelib/tests/data/sample/test_reader/get_read_books_from_web/cache/reader/humming_bird/read/ ~1.html.
Added new 20 entries to ReadBook for Reader None Humming_Bird
Saving 20 books to DB
Page /reader/Humming_Bird/read/~2 is in dump at C:/Users/user/PycharmProjects/livelib-bot/livelib/tests/data/sample/test_reader/get_read_books_from_web/cache/reader/humming_bird/read/ ~2.html.
Added new 19 entries to ReadBook for Reader None Humming_Bird
Saving 19 books to DB
Page /reader/Humming_Bird/read/~3 is in dump at C:/Users/user/PycharmProjects/livelib-bot/livelib/tests/data/sample/test_reader/get_read_books_from_web/cache/reader/humming_bird/read/ ~3.html.
Added new 20 entries to ReadBook for Reader None Humming_Bird
Saving 20 books to DB
Filling update_time of Reader Humming_Bird to 2023-05-24 13:29:58.376994
Delete read books for Reader None Humming_Bird
Adding new Reader to DB: Reader79730124 at id = 359
Filling update_time of Reader Reader79730124 to 2023-05-24 13:29:58.389215
Create DB file C:/Users/user/PycharmProjects/livelib-bot/livelib/tests/data/sample/test_reader\test_has_db_entries.db
Successfully connected to C:/Users/user/PycharmProjects/livelib-bot/livelib/tests/data/sample/test_reader\test_has_db_entries.db db.
Starting to create new database.
Creating new table: CREATE TABLE Book ( id INTEGER PRIMARY KEY AUTOINCREMENT ,book_id INTEGER,work_id INTEGER,book_name TEXT,author_name TEXT,author_id INTEGER,common_rating REAL,picture_url TEXT , UNIQUE(book_id), UNIQUE(work_id) )
Creating new table: CREATE TABLE Reader ( id INTEGER PRIMARY KEY AUTOINCREMENT ,livelib_id INTEGER,login TEXT,update_time TEXT)
Creating new table: CREATE TABLE ReadBook ( id INTEGER PRIMARY KEY AUTOINCREMENT ,book_id INTEGER ,reader_id INTEGER ,review_text TEXT,review_id INTEGER,tags TEXT,reader_rating REAL,month INTEGER,year INTEGER,CONSTRAINT fk_book_id FOREIGN KEY(book_id) REFERENCES Book(id) ON DELETE CASCADE ,CONSTRAINT fk_reader_id FOREIGN KEY(reader_id) REFERENCES Reader(id) ON DELETE CASCADE  UNIQUE(book_id, reader_id))
Remove test database C:/Users/user/PycharmProjects/livelib-bot/livelib/tests/data/sample/test_reader\test_has_db_entries.db
Adding new Reader to DB: Reader81935327 at id = 360
Adding new Reader to DB: Reader61400 at id = 361
Page /reader/Ilaritagli/read/~0 is in dump at C:/Users/user/PycharmProjects/livelib-bot/livelib/tests/data/sample/test_reader/update_books/cache/reader/ilaritagli/read/ ~0.html.
Page /reader/Ilaritagli/read/~1 is in dump at C:/Users/user/PycharmProjects/livelib-bot/livelib/tests/data/sample/test_reader/update_books/cache/reader/ilaritagli/read/ ~1.html.
Added new 0 entries to ReadBook for Reader 347 Ilaritagli
Saving 0 books to DB
Page /reader/Ilaritagli/read/~2 is in dump at C:/Users/user/PycharmProjects/livelib-bot/livelib/tests/data/sample/test_reader/update_books/cache/reader/ilaritagli/read/ ~2.html.
Added new 0 entries to ReadBook for Reader 347 Ilaritagli
Saving 0 books to DB
Page /reader/Ilaritagli/read/~3 is in dump at C:/Users/user/PycharmProjects/livelib-bot/livelib/tests/data/sample/test_reader/update_books/cache/reader/ilaritagli/read/ ~3.html.
Added new 0 entries to ReadBook for Reader 347 Ilaritagli
Saving 0 books to DB
Page /reader/Ilaritagli/read/~4 is in dump at C:/Users/user/PycharmProjects/livelib-bot/livelib/tests/data/sample/test_reader/update_books/cache/reader/ilaritagli/read/ ~4.html.
Added new 0 entries to ReadBook for Reader 347 Ilaritagli
Saving 0 books to DB
Page /reader/Ilaritagli/read/~5 is in dump at C:/Users/user/PycharmProjects/livelib-bot/livelib/tests/data/sample/test_reader/update_books/cache/reader/ilaritagli/read/ ~5.html.
Added new 0 entries to ReadBook for Reader 347 Ilaritagli
Saving 0 books to DB
Filling update_time of Reader Ilaritagli to 2023-05-24 13:29:59.393797
Delete read books for Reader 347 Ilaritagli
Page /reader/Ilaritagli/read/~0 is in dump at C:/Users/user/PycharmProjects/livelib-bot/livelib/tests/data/sample/test_reader/update_books/cache/reader/ilaritagli/read/ ~0.html.
Page /reader/Ilaritagli/read/~1 is in dump at C:/Users/user/PycharmProjects/livelib-bot/livelib/tests/data/sample/test_reader/update_books/cache/reader/ilaritagli/read/ ~1.html.
Added new 20 entries to ReadBook for Reader 347 Ilaritagli
Saving 20 books to DB
Page /reader/Ilaritagli/read/~2 is in dump at C:/Users/user/PycharmProjects/livelib-bot/livelib/tests/data/sample/test_reader/update_books/cache/reader/ilaritagli/read/ ~2.html.
Added new 19 entries to ReadBook for Reader 347 Ilaritagli
Saving 19 books to DB
Page /reader/Ilaritagli/read/~3 is in dump at C:/Users/user/PycharmProjects/livelib-bot/livelib/tests/data/sample/test_reader/update_books/cache/reader/ilaritagli/read/ ~3.html.
Added new 20 entries to ReadBook for Reader 347 Ilaritagli
Saving 20 books to DB
Page /reader/Ilaritagli/read/~4 is in dump at C:/Users/user/PycharmProjects/livelib-bot/livelib/tests/data/sample/test_reader/update_books/cache/reader/ilaritagli/read/ ~4.html.
Added new 20 entries to ReadBook for Reader 347 Ilaritagli
Saving 20 books to DB
Page /reader/Ilaritagli/read/~5 is in dump at C:/Users/user/PycharmProjects/livelib-bot/livelib/tests/data/sample/test_reader/update_books/cache/reader/ilaritagli/read/ ~5.html.
Added new 4 entries to ReadBook for Reader 347 Ilaritagli
Saving 4 books to DB
Filling update_time of Reader Ilaritagli to 2023-05-24 13:29:59.944552
Making request to http://www.example.com
Starting new HTTP connection (1): www.example.com:80
http://www.example.com:80 "GET / HTTP/1.1" 200 648
Making request to http://example4567.com
Starting new HTTP connection (1): example4567.com:80
Can not open this page!
Traceback (most recent call last):
  File "C:\Users\user\PycharmProjects\livelib-bot\venv\lib\site-packages\urllib3\connection.py", line 174, in _new_conn
    conn = connection.create_connection(
  File "C:\Users\user\PycharmProjects\livelib-bot\venv\lib\site-packages\urllib3\util\connection.py", line 72, in create_connection
    for res in socket.getaddrinfo(host, port, family, socket.SOCK_STREAM):
  File "C:\Program Files\Python310\lib\socket.py", line 955, in getaddrinfo
    for res in _socket.getaddrinfo(host, port, family, type, proto, flags):
socket.gaierror: [Errno 11001] getaddrinfo failed

During handling of the above exception, another exception occurred:

Traceback (most recent call last):
  File "C:\Users\user\PycharmProjects\livelib-bot\venv\lib\site-packages\urllib3\connectionpool.py", line 703, in urlopen
    httplib_response = self._make_request(
  File "C:\Users\user\PycharmProjects\livelib-bot\venv\lib\site-packages\urllib3\connectionpool.py", line 398, in _make_request
    conn.request(method, url, **httplib_request_kw)
  File "C:\Users\user\PycharmProjects\livelib-bot\venv\lib\site-packages\urllib3\connection.py", line 244, in request
    super(HTTPConnection, self).request(method, url, body=body, headers=headers)
  File "C:\Program Files\Python310\lib\http\client.py", line 1282, in request
    self._send_request(method, url, body, headers, encode_chunked)
  File "C:\Program Files\Python310\lib\http\client.py", line 1328, in _send_request
    self.endheaders(body, encode_chunked=encode_chunked)
  File "C:\Program Files\Python310\lib\http\client.py", line 1277, in endheaders
    self._send_output(message_body, encode_chunked=encode_chunked)
  File "C:\Program Files\Python310\lib\http\client.py", line 1037, in _send_output
    self.send(msg)
  File "C:\Program Files\Python310\lib\http\client.py", line 975, in send
    self.connect()
  File "C:\Users\user\PycharmProjects\livelib-bot\venv\lib\site-packages\urllib3\connection.py", line 205, in connect
    conn = self._new_conn()
  File "C:\Users\user\PycharmProjects\livelib-bot\venv\lib\site-packages\urllib3\connection.py", line 186, in _new_conn
    raise NewConnectionError(
urllib3.exceptions.NewConnectionError: <urllib3.connection.HTTPConnection object at 0x00000211CA27F250>: Failed to establish a new connection: [Errno 11001] getaddrinfo failed

During handling of the above exception, another exception occurred:

Traceback (most recent call last):
  File "C:\Users\user\PycharmProjects\livelib-bot\venv\lib\site-packages\requests\adapters.py", line 489, in send
    resp = conn.urlopen(
  File "C:\Users\user\PycharmProjects\livelib-bot\venv\lib\site-packages\urllib3\connectionpool.py", line 787, in urlopen
    retries = retries.increment(
  File "C:\Users\user\PycharmProjects\livelib-bot\venv\lib\site-packages\urllib3\util\retry.py", line 592, in increment
    raise MaxRetryError(_pool, url, error or ResponseError(cause))
urllib3.exceptions.MaxRetryError: HTTPConnectionPool(host='example4567.com', port=80): Max retries exceeded with url: / (Caused by NewConnectionError('<urllib3.connection.HTTPConnection object at 0x00000211CA27F250>: Failed to establish a new connection: [Errno 11001] getaddrinfo failed'))

During handling of the above exception, another exception occurred:

Traceback (most recent call last):
  File "C:\Users\user\PycharmProjects\livelib-bot\livelib\webconnection.py", line 139, in _get_page
    result = requests.get(url, headers=headers)
  File "C:\Users\user\PycharmProjects\livelib-bot\venv\lib\site-packages\requests\api.py", line 73, in get
    return request("get", url, params=params, **kwargs)
  File "C:\Users\user\PycharmProjects\livelib-bot\venv\lib\site-packages\requests\api.py", line 59, in request
    return session.request(method=method, url=url, **kwargs)
  File "C:\Users\user\PycharmProjects\livelib-bot\venv\lib\site-packages\requests\sessions.py", line 587, in request
    resp = self.send(prep, **send_kwargs)
  File "C:\Users\user\PycharmProjects\livelib-bot\venv\lib\site-packages\requests\sessions.py", line 701, in send
    r = adapter.send(request, **kwargs)
  File "C:\Users\user\PycharmProjects\livelib-bot\venv\lib\site-packages\requests\adapters.py", line 565, in send
    raise ConnectionError(e, request=request)
requests.exceptions.ConnectionError: HTTPConnectionPool(host='example4567.com', port=80): Max retries exceeded with url: / (Caused by NewConnectionError('<urllib3.connection.HTTPConnection object at 0x00000211CA27F250>: Failed to establish a new connection: [Errno 11001] getaddrinfo failed'))
Can not get text from page! http://example4567.com
Traceback (most recent call last):
  File "C:\Users\user\PycharmProjects\livelib-bot\venv\lib\site-packages\urllib3\connection.py", line 174, in _new_conn
    conn = connection.create_connection(
  File "C:\Users\user\PycharmProjects\livelib-bot\venv\lib\site-packages\urllib3\util\connection.py", line 72, in create_connection
    for res in socket.getaddrinfo(host, port, family, socket.SOCK_STREAM):
  File "C:\Program Files\Python310\lib\socket.py", line 955, in getaddrinfo
    for res in _socket.getaddrinfo(host, port, family, type, proto, flags):
socket.gaierror: [Errno 11001] getaddrinfo failed

During handling of the above exception, another exception occurred:

Traceback (most recent call last):
  File "C:\Users\user\PycharmProjects\livelib-bot\venv\lib\site-packages\urllib3\connectionpool.py", line 703, in urlopen
    httplib_response = self._make_request(
  File "C:\Users\user\PycharmProjects\livelib-bot\venv\lib\site-packages\urllib3\connectionpool.py", line 398, in _make_request
    conn.request(method, url, **httplib_request_kw)
  File "C:\Users\user\PycharmProjects\livelib-bot\venv\lib\site-packages\urllib3\connection.py", line 244, in request
    super(HTTPConnection, self).request(method, url, body=body, headers=headers)
  File "C:\Program Files\Python310\lib\http\client.py", line 1282, in request
    self._send_request(method, url, body, headers, encode_chunked)
  File "C:\Program Files\Python310\lib\http\client.py", line 1328, in _send_request
    self.endheaders(body, encode_chunked=encode_chunked)
  File "C:\Program Files\Python310\lib\http\client.py", line 1277, in endheaders
    self._send_output(message_body, encode_chunked=encode_chunked)
  File "C:\Program Files\Python310\lib\http\client.py", line 1037, in _send_output
    self.send(msg)
  File "C:\Program Files\Python310\lib\http\client.py", line 975, in send
    self.connect()
  File "C:\Users\user\PycharmProjects\livelib-bot\venv\lib\site-packages\urllib3\connection.py", line 205, in connect
    conn = self._new_conn()
  File "C:\Users\user\PycharmProjects\livelib-bot\venv\lib\site-packages\urllib3\connection.py", line 186, in _new_conn
    raise NewConnectionError(
urllib3.exceptions.NewConnectionError: <urllib3.connection.HTTPConnection object at 0x00000211CA27F250>: Failed to establish a new connection: [Errno 11001] getaddrinfo failed

During handling of the above exception, another exception occurred:

Traceback (most recent call last):
  File "C:\Users\user\PycharmProjects\livelib-bot\venv\lib\site-packages\requests\adapters.py", line 489, in send
    resp = conn.urlopen(
  File "C:\Users\user\PycharmProjects\livelib-bot\venv\lib\site-packages\urllib3\connectionpool.py", line 787, in urlopen
    retries = retries.increment(
  File "C:\Users\user\PycharmProjects\livelib-bot\venv\lib\site-packages\urllib3\util\retry.py", line 592, in increment
    raise MaxRetryError(_pool, url, error or ResponseError(cause))
urllib3.exceptions.MaxRetryError: HTTPConnectionPool(host='example4567.com', port=80): Max retries exceeded with url: / (Caused by NewConnectionError('<urllib3.connection.HTTPConnection object at 0x00000211CA27F250>: Failed to establish a new connection: [Errno 11001] getaddrinfo failed'))

During handling of the above exception, another exception occurred:

Traceback (most recent call last):
  File "C:\Users\user\PycharmProjects\livelib-bot\livelib\webconnection.py", line 168, in get_page_text
    page = self._get_page(url)
  File "C:\Users\user\PycharmProjects\livelib-bot\livelib\webconnection.py", line 139, in _get_page
    result = requests.get(url, headers=headers)
  File "C:\Users\user\PycharmProjects\livelib-bot\venv\lib\site-packages\requests\api.py", line 73, in get
    return request("get", url, params=params, **kwargs)
  File "C:\Users\user\PycharmProjects\livelib-bot\venv\lib\site-packages\requests\api.py", line 59, in request
    return session.request(method=method, url=url, **kwargs)
  File "C:\Users\user\PycharmProjects\livelib-bot\venv\lib\site-packages\requests\sessions.py", line 587, in request
    resp = self.send(prep, **send_kwargs)
  File "C:\Users\user\PycharmProjects\livelib-bot\venv\lib\site-packages\requests\sessions.py", line 701, in send
    r = adapter.send(request, **kwargs)
  File "C:\Users\user\PycharmProjects\livelib-bot\venv\lib\site-packages\requests\adapters.py", line 565, in send
    raise ConnectionError(e, request=request)
requests.exceptions.ConnectionError: HTTPConnectionPool(host='example4567.com', port=80): Max retries exceeded with url: / (Caused by NewConnectionError('<urllib3.connection.HTTPConnection object at 0x00000211CA27F250>: Failed to establish a new connection: [Errno 11001] getaddrinfo failed'))
Can not get BS object from http://example4567.com
Traceback (most recent call last):
  File "C:\Users\user\PycharmProjects\livelib-bot\venv\lib\site-packages\urllib3\connection.py", line 174, in _new_conn
    conn = connection.create_connection(
  File "C:\Users\user\PycharmProjects\livelib-bot\venv\lib\site-packages\urllib3\util\connection.py", line 72, in create_connection
    for res in socket.getaddrinfo(host, port, family, socket.SOCK_STREAM):
  File "C:\Program Files\Python310\lib\socket.py", line 955, in getaddrinfo
    for res in _socket.getaddrinfo(host, port, family, type, proto, flags):
socket.gaierror: [Errno 11001] getaddrinfo failed

During handling of the above exception, another exception occurred:

Traceback (most recent call last):
  File "C:\Users\user\PycharmProjects\livelib-bot\venv\lib\site-packages\urllib3\connectionpool.py", line 703, in urlopen
    httplib_response = self._make_request(
  File "C:\Users\user\PycharmProjects\livelib-bot\venv\lib\site-packages\urllib3\connectionpool.py", line 398, in _make_request
    conn.request(method, url, **httplib_request_kw)
  File "C:\Users\user\PycharmProjects\livelib-bot\venv\lib\site-packages\urllib3\connection.py", line 244, in request
    super(HTTPConnection, self).request(method, url, body=body, headers=headers)
  File "C:\Program Files\Python310\lib\http\client.py", line 1282, in request
    self._send_request(method, url, body, headers, encode_chunked)
  File "C:\Program Files\Python310\lib\http\client.py", line 1328, in _send_request
    self.endheaders(body, encode_chunked=encode_chunked)
  File "C:\Program Files\Python310\lib\http\client.py", line 1277, in endheaders
    self._send_output(message_body, encode_chunked=encode_chunked)
  File "C:\Program Files\Python310\lib\http\client.py", line 1037, in _send_output
    self.send(msg)
  File "C:\Program Files\Python310\lib\http\client.py", line 975, in send
    self.connect()
  File "C:\Users\user\PycharmProjects\livelib-bot\venv\lib\site-packages\urllib3\connection.py", line 205, in connect
    conn = self._new_conn()
  File "C:\Users\user\PycharmProjects\livelib-bot\venv\lib\site-packages\urllib3\connection.py", line 186, in _new_conn
    raise NewConnectionError(
urllib3.exceptions.NewConnectionError: <urllib3.connection.HTTPConnection object at 0x00000211CA27F250>: Failed to establish a new connection: [Errno 11001] getaddrinfo failed

During handling of the above exception, another exception occurred:

Traceback (most recent call last):
  File "C:\Users\user\PycharmProjects\livelib-bot\venv\lib\site-packages\requests\adapters.py", line 489, in send
    resp = conn.urlopen(
  File "C:\Users\user\PycharmProjects\livelib-bot\venv\lib\site-packages\urllib3\connectionpool.py", line 787, in urlopen
    retries = retries.increment(
  File "C:\Users\user\PycharmProjects\livelib-bot\venv\lib\site-packages\urllib3\util\retry.py", line 592, in increment
    raise MaxRetryError(_pool, url, error or ResponseError(cause))
urllib3.exceptions.MaxRetryError: HTTPConnectionPool(host='example4567.com', port=80): Max retries exceeded with url: / (Caused by NewConnectionError('<urllib3.connection.HTTPConnection object at 0x00000211CA27F250>: Failed to establish a new connection: [Errno 11001] getaddrinfo failed'))

During handling of the above exception, another exception occurred:

Traceback (most recent call last):
  File "C:\Users\user\PycharmProjects\livelib-bot\livelib\webconnection.py", line 52, in _get_page_bs
    result = bs4.BeautifulSoup(self.get_page_text(url), features='lxml')
  File "C:\Users\user\PycharmProjects\livelib-bot\livelib\webconnection.py", line 168, in get_page_text
    page = self._get_page(url)
  File "C:\Users\user\PycharmProjects\livelib-bot\livelib\webconnection.py", line 139, in _get_page
    result = requests.get(url, headers=headers)
  File "C:\Users\user\PycharmProjects\livelib-bot\venv\lib\site-packages\requests\api.py", line 73, in get
    return request("get", url, params=params, **kwargs)
  File "C:\Users\user\PycharmProjects\livelib-bot\venv\lib\site-packages\requests\api.py", line 59, in request
    return session.request(method=method, url=url, **kwargs)
  File "C:\Users\user\PycharmProjects\livelib-bot\venv\lib\site-packages\requests\sessions.py", line 587, in request
    resp = self.send(prep, **send_kwargs)
  File "C:\Users\user\PycharmProjects\livelib-bot\venv\lib\site-packages\requests\sessions.py", line 701, in send
    r = adapter.send(request, **kwargs)
  File "C:\Users\user\PycharmProjects\livelib-bot\venv\lib\site-packages\requests\adapters.py", line 565, in send
    raise ConnectionError(e, request=request)
requests.exceptions.ConnectionError: HTTPConnectionPool(host='example4567.com', port=80): Max retries exceeded with url: / (Caused by NewConnectionError('<urllib3.connection.HTTPConnection object at 0x00000211CA27F250>: Failed to establish a new connection: [Errno 11001] getaddrinfo failed'))
Making request to http://www.livelib.ru
Starting new HTTP connection (1): www.livelib.ru:80
http://www.livelib.ru:80 "GET / HTTP/1.1" 302 138
Starting new HTTPS connection (1): www.livelib.ru:443
https://www.livelib.ru:443 "GET / HTTP/1.1" 200 None
Making request to http://www.yandex.com
Starting new HTTP connection (1): www.yandex.com:80
http://www.yandex.com:80 "GET / HTTP/1.1" 302 None
Starting new HTTPS connection (1): yandex.com:443
https://yandex.com:443 "GET / HTTP/1.1" 200 None
Making request to http://www.example.com
Starting new HTTP connection (1): www.example.com:80
http://www.example.com:80 "GET / HTTP/1.1" 200 648
Making request to http://example4567.com
Starting new HTTP connection (1): example4567.com:80
Can not open this page!
Traceback (most recent call last):
  File "C:\Users\user\PycharmProjects\livelib-bot\venv\lib\site-packages\urllib3\connection.py", line 174, in _new_conn
    conn = connection.create_connection(
  File "C:\Users\user\PycharmProjects\livelib-bot\venv\lib\site-packages\urllib3\util\connection.py", line 72, in create_connection
    for res in socket.getaddrinfo(host, port, family, socket.SOCK_STREAM):
  File "C:\Program Files\Python310\lib\socket.py", line 955, in getaddrinfo
    for res in _socket.getaddrinfo(host, port, family, type, proto, flags):
socket.gaierror: [Errno 11001] getaddrinfo failed

During handling of the above exception, another exception occurred:

Traceback (most recent call last):
  File "C:\Users\user\PycharmProjects\livelib-bot\venv\lib\site-packages\urllib3\connectionpool.py", line 703, in urlopen
    httplib_response = self._make_request(
  File "C:\Users\user\PycharmProjects\livelib-bot\venv\lib\site-packages\urllib3\connectionpool.py", line 398, in _make_request
    conn.request(method, url, **httplib_request_kw)
  File "C:\Users\user\PycharmProjects\livelib-bot\venv\lib\site-packages\urllib3\connection.py", line 244, in request
    super(HTTPConnection, self).request(method, url, body=body, headers=headers)
  File "C:\Program Files\Python310\lib\http\client.py", line 1282, in request
    self._send_request(method, url, body, headers, encode_chunked)
  File "C:\Program Files\Python310\lib\http\client.py", line 1328, in _send_request
    self.endheaders(body, encode_chunked=encode_chunked)
  File "C:\Program Files\Python310\lib\http\client.py", line 1277, in endheaders
    self._send_output(message_body, encode_chunked=encode_chunked)
  File "C:\Program Files\Python310\lib\http\client.py", line 1037, in _send_output
    self.send(msg)
  File "C:\Program Files\Python310\lib\http\client.py", line 975, in send
    self.connect()
  File "C:\Users\user\PycharmProjects\livelib-bot\venv\lib\site-packages\urllib3\connection.py", line 205, in connect
    conn = self._new_conn()
  File "C:\Users\user\PycharmProjects\livelib-bot\venv\lib\site-packages\urllib3\connection.py", line 186, in _new_conn
    raise NewConnectionError(
urllib3.exceptions.NewConnectionError: <urllib3.connection.HTTPConnection object at 0x00000211C9DAF370>: Failed to establish a new connection: [Errno 11001] getaddrinfo failed

During handling of the above exception, another exception occurred:

Traceback (most recent call last):
  File "C:\Users\user\PycharmProjects\livelib-bot\venv\lib\site-packages\requests\adapters.py", line 489, in send
    resp = conn.urlopen(
  File "C:\Users\user\PycharmProjects\livelib-bot\venv\lib\site-packages\urllib3\connectionpool.py", line 787, in urlopen
    retries = retries.increment(
  File "C:\Users\user\PycharmProjects\livelib-bot\venv\lib\site-packages\urllib3\util\retry.py", line 592, in increment
    raise MaxRetryError(_pool, url, error or ResponseError(cause))
urllib3.exceptions.MaxRetryError: HTTPConnectionPool(host='example4567.com', port=80): Max retries exceeded with url: / (Caused by NewConnectionError('<urllib3.connection.HTTPConnection object at 0x00000211C9DAF370>: Failed to establish a new connection: [Errno 11001] getaddrinfo failed'))

During handling of the above exception, another exception occurred:

Traceback (most recent call last):
  File "C:\Users\user\PycharmProjects\livelib-bot\livelib\webconnection.py", line 139, in _get_page
    result = requests.get(url, headers=headers)
  File "C:\Users\user\PycharmProjects\livelib-bot\venv\lib\site-packages\requests\api.py", line 73, in get
    return request("get", url, params=params, **kwargs)
  File "C:\Users\user\PycharmProjects\livelib-bot\venv\lib\site-packages\requests\api.py", line 59, in request
    return session.request(method=method, url=url, **kwargs)
  File "C:\Users\user\PycharmProjects\livelib-bot\venv\lib\site-packages\requests\sessions.py", line 587, in request
    resp = self.send(prep, **send_kwargs)
  File "C:\Users\user\PycharmProjects\livelib-bot\venv\lib\site-packages\requests\sessions.py", line 701, in send
    r = adapter.send(request, **kwargs)
  File "C:\Users\user\PycharmProjects\livelib-bot\venv\lib\site-packages\requests\adapters.py", line 565, in send
    raise ConnectionError(e, request=request)
requests.exceptions.ConnectionError: HTTPConnectionPool(host='example4567.com', port=80): Max retries exceeded with url: / (Caused by NewConnectionError('<urllib3.connection.HTTPConnection object at 0x00000211C9DAF370>: Failed to establish a new connection: [Errno 11001] getaddrinfo failed'))
Making request to http://www.livelib.ru
Starting new HTTP connection (1): www.livelib.ru:80
http://www.livelib.ru:80 "GET / HTTP/1.1" 302 138
Starting new HTTPS connection (1): www.livelib.ru:443
https://www.livelib.ru:443 "GET / HTTP/1.1" 200 None
Making request to http://www.yandex.com
Starting new HTTP connection (1): www.yandex.com:80
http://www.yandex.com:80 "GET / HTTP/1.1" 302 None
http://www.yandex.com:80 "GET /showcaptcha?cc=1&mt=00493F763D2DBD17FB9B71D4EFBE28624EE8074BDADE2371A98C342E1231FC63FE1F64D02555C4C28B751D498A53AB1935A3FF5532827162DE64F252020A4BED249634AD33B5A8E335299EEA77E6D2F386D5A704442D9D1BC35C&retpath=aHR0cDovL3d3dy55YW5kZXguY29tLz8%2C_03325bfc427335a7d143da493e8c7883&t=2/1684924201/133f311cfe229308718c3bcf584728a6&u=1b7f8c59-f200c4b9-fff01d1e-2738fe95&s=10c34d4ea03353d9736661cea05eb658 HTTP/1.1" 200 13083
Making request to http://www.example.com
Starting new HTTP connection (1): www.example.com:80
http://www.example.com:80 "GET / HTTP/1.1" 200 648
Making request to http://example4567.com
Starting new HTTP connection (1): example4567.com:80
Can not open this page!
Traceback (most recent call last):
  File "C:\Users\user\PycharmProjects\livelib-bot\venv\lib\site-packages\urllib3\connection.py", line 174, in _new_conn
    conn = connection.create_connection(
  File "C:\Users\user\PycharmProjects\livelib-bot\venv\lib\site-packages\urllib3\util\connection.py", line 72, in create_connection
    for res in socket.getaddrinfo(host, port, family, socket.SOCK_STREAM):
  File "C:\Program Files\Python310\lib\socket.py", line 955, in getaddrinfo
    for res in _socket.getaddrinfo(host, port, family, type, proto, flags):
socket.gaierror: [Errno 11001] getaddrinfo failed

During handling of the above exception, another exception occurred:

Traceback (most recent call last):
  File "C:\Users\user\PycharmProjects\livelib-bot\venv\lib\site-packages\urllib3\connectionpool.py", line 703, in urlopen
    httplib_response = self._make_request(
  File "C:\Users\user\PycharmProjects\livelib-bot\venv\lib\site-packages\urllib3\connectionpool.py", line 398, in _make_request
    conn.request(method, url, **httplib_request_kw)
  File "C:\Users\user\PycharmProjects\livelib-bot\venv\lib\site-packages\urllib3\connection.py", line 244, in request
    super(HTTPConnection, self).request(method, url, body=body, headers=headers)
  File "C:\Program Files\Python310\lib\http\client.py", line 1282, in request
    self._send_request(method, url, body, headers, encode_chunked)
  File "C:\Program Files\Python310\lib\http\client.py", line 1328, in _send_request
    self.endheaders(body, encode_chunked=encode_chunked)
  File "C:\Program Files\Python310\lib\http\client.py", line 1277, in endheaders
    self._send_output(message_body, encode_chunked=encode_chunked)
  File "C:\Program Files\Python310\lib\http\client.py", line 1037, in _send_output
    self.send(msg)
  File "C:\Program Files\Python310\lib\http\client.py", line 975, in send
    self.connect()
  File "C:\Users\user\PycharmProjects\livelib-bot\venv\lib\site-packages\urllib3\connection.py", line 205, in connect
    conn = self._new_conn()
  File "C:\Users\user\PycharmProjects\livelib-bot\venv\lib\site-packages\urllib3\connection.py", line 186, in _new_conn
    raise NewConnectionError(
urllib3.exceptions.NewConnectionError: <urllib3.connection.HTTPConnection object at 0x00000211C9D68040>: Failed to establish a new connection: [Errno 11001] getaddrinfo failed

During handling of the above exception, another exception occurred:

Traceback (most recent call last):
  File "C:\Users\user\PycharmProjects\livelib-bot\venv\lib\site-packages\requests\adapters.py", line 489, in send
    resp = conn.urlopen(
  File "C:\Users\user\PycharmProjects\livelib-bot\venv\lib\site-packages\urllib3\connectionpool.py", line 787, in urlopen
    retries = retries.increment(
  File "C:\Users\user\PycharmProjects\livelib-bot\venv\lib\site-packages\urllib3\util\retry.py", line 592, in increment
    raise MaxRetryError(_pool, url, error or ResponseError(cause))
urllib3.exceptions.MaxRetryError: HTTPConnectionPool(host='example4567.com', port=80): Max retries exceeded with url: / (Caused by NewConnectionError('<urllib3.connection.HTTPConnection object at 0x00000211C9D68040>: Failed to establish a new connection: [Errno 11001] getaddrinfo failed'))

During handling of the above exception, another exception occurred:

Traceback (most recent call last):
  File "C:\Users\user\PycharmProjects\livelib-bot\livelib\webconnection.py", line 139, in _get_page
    result = requests.get(url, headers=headers)
  File "C:\Users\user\PycharmProjects\livelib-bot\venv\lib\site-packages\requests\api.py", line 73, in get
    return request("get", url, params=params, **kwargs)
  File "C:\Users\user\PycharmProjects\livelib-bot\venv\lib\site-packages\requests\api.py", line 59, in request
    return session.request(method=method, url=url, **kwargs)
  File "C:\Users\user\PycharmProjects\livelib-bot\venv\lib\site-packages\requests\sessions.py", line 587, in request
    resp = self.send(prep, **send_kwargs)
  File "C:\Users\user\PycharmProjects\livelib-bot\venv\lib\site-packages\requests\sessions.py", line 701, in send
    r = adapter.send(request, **kwargs)
  File "C:\Users\user\PycharmProjects\livelib-bot\venv\lib\site-packages\requests\adapters.py", line 565, in send
    raise ConnectionError(e, request=request)
requests.exceptions.ConnectionError: HTTPConnectionPool(host='example4567.com', port=80): Max retries exceeded with url: / (Caused by NewConnectionError('<urllib3.connection.HTTPConnection object at 0x00000211C9D68040>: Failed to establish a new connection: [Errno 11001] getaddrinfo failed'))
Can not get text from page! http://example4567.com
Traceback (most recent call last):
  File "C:\Users\user\PycharmProjects\livelib-bot\venv\lib\site-packages\urllib3\connection.py", line 174, in _new_conn
    conn = connection.create_connection(
  File "C:\Users\user\PycharmProjects\livelib-bot\venv\lib\site-packages\urllib3\util\connection.py", line 72, in create_connection
    for res in socket.getaddrinfo(host, port, family, socket.SOCK_STREAM):
  File "C:\Program Files\Python310\lib\socket.py", line 955, in getaddrinfo
    for res in _socket.getaddrinfo(host, port, family, type, proto, flags):
socket.gaierror: [Errno 11001] getaddrinfo failed

During handling of the above exception, another exception occurred:

Traceback (most recent call last):
  File "C:\Users\user\PycharmProjects\livelib-bot\venv\lib\site-packages\urllib3\connectionpool.py", line 703, in urlopen
    httplib_response = self._make_request(
  File "C:\Users\user\PycharmProjects\livelib-bot\venv\lib\site-packages\urllib3\connectionpool.py", line 398, in _make_request
    conn.request(method, url, **httplib_request_kw)
  File "C:\Users\user\PycharmProjects\livelib-bot\venv\lib\site-packages\urllib3\connection.py", line 244, in request
    super(HTTPConnection, self).request(method, url, body=body, headers=headers)
  File "C:\Program Files\Python310\lib\http\client.py", line 1282, in request
    self._send_request(method, url, body, headers, encode_chunked)
  File "C:\Program Files\Python310\lib\http\client.py", line 1328, in _send_request
    self.endheaders(body, encode_chunked=encode_chunked)
  File "C:\Program Files\Python310\lib\http\client.py", line 1277, in endheaders
    self._send_output(message_body, encode_chunked=encode_chunked)
  File "C:\Program Files\Python310\lib\http\client.py", line 1037, in _send_output
    self.send(msg)
  File "C:\Program Files\Python310\lib\http\client.py", line 975, in send
    self.connect()
  File "C:\Users\user\PycharmProjects\livelib-bot\venv\lib\site-packages\urllib3\connection.py", line 205, in connect
    conn = self._new_conn()
  File "C:\Users\user\PycharmProjects\livelib-bot\venv\lib\site-packages\urllib3\connection.py", line 186, in _new_conn
    raise NewConnectionError(
urllib3.exceptions.NewConnectionError: <urllib3.connection.HTTPConnection object at 0x00000211C9D68040>: Failed to establish a new connection: [Errno 11001] getaddrinfo failed

During handling of the above exception, another exception occurred:

Traceback (most recent call last):
  File "C:\Users\user\PycharmProjects\livelib-bot\venv\lib\site-packages\requests\adapters.py", line 489, in send
    resp = conn.urlopen(
  File "C:\Users\user\PycharmProjects\livelib-bot\venv\lib\site-packages\urllib3\connectionpool.py", line 787, in urlopen
    retries = retries.increment(
  File "C:\Users\user\PycharmProjects\livelib-bot\venv\lib\site-packages\urllib3\util\retry.py", line 592, in increment
    raise MaxRetryError(_pool, url, error or ResponseError(cause))
urllib3.exceptions.MaxRetryError: HTTPConnectionPool(host='example4567.com', port=80): Max retries exceeded with url: / (Caused by NewConnectionError('<urllib3.connection.HTTPConnection object at 0x00000211C9D68040>: Failed to establish a new connection: [Errno 11001] getaddrinfo failed'))

During handling of the above exception, another exception occurred:

Traceback (most recent call last):
  File "C:\Users\user\PycharmProjects\livelib-bot\livelib\webconnection.py", line 168, in get_page_text
    page = self._get_page(url)
  File "C:\Users\user\PycharmProjects\livelib-bot\livelib\webconnection.py", line 139, in _get_page
    result = requests.get(url, headers=headers)
  File "C:\Users\user\PycharmProjects\livelib-bot\venv\lib\site-packages\requests\api.py", line 73, in get
    return request("get", url, params=params, **kwargs)
  File "C:\Users\user\PycharmProjects\livelib-bot\venv\lib\site-packages\requests\api.py", line 59, in request
    return session.request(method=method, url=url, **kwargs)
  File "C:\Users\user\PycharmProjects\livelib-bot\venv\lib\site-packages\requests\sessions.py", line 587, in request
    resp = self.send(prep, **send_kwargs)
  File "C:\Users\user\PycharmProjects\livelib-bot\venv\lib\site-packages\requests\sessions.py", line 701, in send
    r = adapter.send(request, **kwargs)
  File "C:\Users\user\PycharmProjects\livelib-bot\venv\lib\site-packages\requests\adapters.py", line 565, in send
    raise ConnectionError(e, request=request)
requests.exceptions.ConnectionError: HTTPConnectionPool(host='example4567.com', port=80): Max retries exceeded with url: / (Caused by NewConnectionError('<urllib3.connection.HTTPConnection object at 0x00000211C9D68040>: Failed to establish a new connection: [Errno 11001] getaddrinfo failed'))
Can not get BS object from http://example4567.com
Traceback (most recent call last):
  File "C:\Users\user\PycharmProjects\livelib-bot\venv\lib\site-packages\urllib3\connection.py", line 174, in _new_conn
    conn = connection.create_connection(
  File "C:\Users\user\PycharmProjects\livelib-bot\venv\lib\site-packages\urllib3\util\connection.py", line 72, in create_connection
    for res in socket.getaddrinfo(host, port, family, socket.SOCK_STREAM):
  File "C:\Program Files\Python310\lib\socket.py", line 955, in getaddrinfo
    for res in _socket.getaddrinfo(host, port, family, type, proto, flags):
socket.gaierror: [Errno 11001] getaddrinfo failed

During handling of the above exception, another exception occurred:

Traceback (most recent call last):
  File "C:\Users\user\PycharmProjects\livelib-bot\venv\lib\site-packages\urllib3\connectionpool.py", line 703, in urlopen
    httplib_response = self._make_request(
  File "C:\Users\user\PycharmProjects\livelib-bot\venv\lib\site-packages\urllib3\connectionpool.py", line 398, in _make_request
    conn.request(method, url, **httplib_request_kw)
  File "C:\Users\user\PycharmProjects\livelib-bot\venv\lib\site-packages\urllib3\connection.py", line 244, in request
    super(HTTPConnection, self).request(method, url, body=body, headers=headers)
  File "C:\Program Files\Python310\lib\http\client.py", line 1282, in request
    self._send_request(method, url, body, headers, encode_chunked)
  File "C:\Program Files\Python310\lib\http\client.py", line 1328, in _send_request
    self.endheaders(body, encode_chunked=encode_chunked)
  File "C:\Program Files\Python310\lib\http\client.py", line 1277, in endheaders
    self._send_output(message_body, encode_chunked=encode_chunked)
  File "C:\Program Files\Python310\lib\http\client.py", line 1037, in _send_output
    self.send(msg)
  File "C:\Program Files\Python310\lib\http\client.py", line 975, in send
    self.connect()
  File "C:\Users\user\PycharmProjects\livelib-bot\venv\lib\site-packages\urllib3\connection.py", line 205, in connect
    conn = self._new_conn()
  File "C:\Users\user\PycharmProjects\livelib-bot\venv\lib\site-packages\urllib3\connection.py", line 186, in _new_conn
    raise NewConnectionError(
urllib3.exceptions.NewConnectionError: <urllib3.connection.HTTPConnection object at 0x00000211C9D68040>: Failed to establish a new connection: [Errno 11001] getaddrinfo failed

During handling of the above exception, another exception occurred:

Traceback (most recent call last):
  File "C:\Users\user\PycharmProjects\livelib-bot\venv\lib\site-packages\requests\adapters.py", line 489, in send
    resp = conn.urlopen(
  File "C:\Users\user\PycharmProjects\livelib-bot\venv\lib\site-packages\urllib3\connectionpool.py", line 787, in urlopen
    retries = retries.increment(
  File "C:\Users\user\PycharmProjects\livelib-bot\venv\lib\site-packages\urllib3\util\retry.py", line 592, in increment
    raise MaxRetryError(_pool, url, error or ResponseError(cause))
urllib3.exceptions.MaxRetryError: HTTPConnectionPool(host='example4567.com', port=80): Max retries exceeded with url: / (Caused by NewConnectionError('<urllib3.connection.HTTPConnection object at 0x00000211C9D68040>: Failed to establish a new connection: [Errno 11001] getaddrinfo failed'))

During handling of the above exception, another exception occurred:

Traceback (most recent call last):
  File "C:\Users\user\PycharmProjects\livelib-bot\livelib\webconnection.py", line 73, in get_page_bs
    result = bs4.BeautifulSoup(self.get_page_text(url), features='lxml')
  File "C:\Users\user\PycharmProjects\livelib-bot\livelib\webconnection.py", line 168, in get_page_text
    page = self._get_page(url)
  File "C:\Users\user\PycharmProjects\livelib-bot\livelib\webconnection.py", line 139, in _get_page
    result = requests.get(url, headers=headers)
  File "C:\Users\user\PycharmProjects\livelib-bot\venv\lib\site-packages\requests\api.py", line 73, in get
    return request("get", url, params=params, **kwargs)
  File "C:\Users\user\PycharmProjects\livelib-bot\venv\lib\site-packages\requests\api.py", line 59, in request
    return session.request(method=method, url=url, **kwargs)
  File "C:\Users\user\PycharmProjects\livelib-bot\venv\lib\site-packages\requests\sessions.py", line 587, in request
    resp = self.send(prep, **send_kwargs)
  File "C:\Users\user\PycharmProjects\livelib-bot\venv\lib\site-packages\requests\sessions.py", line 701, in send
    r = adapter.send(request, **kwargs)
  File "C:\Users\user\PycharmProjects\livelib-bot\venv\lib\site-packages\requests\adapters.py", line 565, in send
    raise ConnectionError(e, request=request)
requests.exceptions.ConnectionError: HTTPConnectionPool(host='example4567.com', port=80): Max retries exceeded with url: / (Caused by NewConnectionError('<urllib3.connection.HTTPConnection object at 0x00000211C9D68040>: Failed to establish a new connection: [Errno 11001] getaddrinfo failed'))
Making request to http://www.livelib.ru
Starting new HTTP connection (1): www.livelib.ru:80
http://www.livelib.ru:80 "GET / HTTP/1.1" 302 138
Starting new HTTPS connection (1): www.livelib.ru:443
https://www.livelib.ru:443 "GET / HTTP/1.1" 200 None
Making request to http://www.livelib.ru/jsndjsdnljdncldn/
Starting new HTTP connection (1): www.livelib.ru:80
http://www.livelib.ru:80 "GET /jsndjsdnljdncldn/ HTTP/1.1" 302 138
Starting new HTTPS connection (1): www.livelib.ru:443
https://www.livelib.ru:443 "GET /jsndjsdnljdncldn/ HTTP/1.1" 301 None
https://www.livelib.ru:443 "GET /jsndjsdnljdncldn HTTP/1.1" 404 None
Page at http://www.livelib.ru/jsndjsdnljdncldn/ is 404!
Making request to http://www.livelib.ru/reader/alkasnmklas
Starting new HTTP connection (1): www.livelib.ru:80
http://www.livelib.ru:80 "GET /reader/alkasnmklas HTTP/1.1" 302 138
Starting new HTTPS connection (1): www.livelib.ru:443
https://www.livelib.ru:443 "GET /reader/alkasnmklas HTTP/1.1" 404 None
Page at http://www.livelib.ru/reader/alkasnmklas is 404!
Making request to http://www.livelib.ru/reader/feana
Starting new HTTP connection (1): www.livelib.ru:80
http://www.livelib.ru:80 "GET /reader/feana HTTP/1.1" 302 138
Starting new HTTPS connection (1): www.livelib.ru:443
https://www.livelib.ru:443 "GET /reader/feana HTTP/1.1" 301 None
https://www.livelib.ru:443 "GET /reader/Feana HTTP/1.1" 200 None
Making request to http://www.google.com
Starting new HTTP connection (1): www.google.com:80
http://www.google.com:80 "GET / HTTP/1.1" 302 231
Starting new HTTPS connection (1): www.google.com:443
https://www.google.com:443 "GET /?gws_rd=ssl HTTP/1.1" 200 None
Making request to http://www.example.com
Starting new HTTP connection (1): www.example.com:80
http://www.example.com:80 "GET / HTTP/1.1" 200 648
Making request to http://example4567.com
Starting new HTTP connection (1): example4567.com:80
Can not open this page!
Traceback (most recent call last):
  File "C:\Users\user\PycharmProjects\livelib-bot\venv\lib\site-packages\urllib3\connection.py", line 174, in _new_conn
    conn = connection.create_connection(
  File "C:\Users\user\PycharmProjects\livelib-bot\venv\lib\site-packages\urllib3\util\connection.py", line 72, in create_connection
    for res in socket.getaddrinfo(host, port, family, socket.SOCK_STREAM):
  File "C:\Program Files\Python310\lib\socket.py", line 955, in getaddrinfo
    for res in _socket.getaddrinfo(host, port, family, type, proto, flags):
socket.gaierror: [Errno 11001] getaddrinfo failed

During handling of the above exception, another exception occurred:

Traceback (most recent call last):
  File "C:\Users\user\PycharmProjects\livelib-bot\venv\lib\site-packages\urllib3\connectionpool.py", line 703, in urlopen
    httplib_response = self._make_request(
  File "C:\Users\user\PycharmProjects\livelib-bot\venv\lib\site-packages\urllib3\connectionpool.py", line 398, in _make_request
    conn.request(method, url, **httplib_request_kw)
  File "C:\Users\user\PycharmProjects\livelib-bot\venv\lib\site-packages\urllib3\connection.py", line 244, in request
    super(HTTPConnection, self).request(method, url, body=body, headers=headers)
  File "C:\Program Files\Python310\lib\http\client.py", line 1282, in request
    self._send_request(method, url, body, headers, encode_chunked)
  File "C:\Program Files\Python310\lib\http\client.py", line 1328, in _send_request
    self.endheaders(body, encode_chunked=encode_chunked)
  File "C:\Program Files\Python310\lib\http\client.py", line 1277, in endheaders
    self._send_output(message_body, encode_chunked=encode_chunked)
  File "C:\Program Files\Python310\lib\http\client.py", line 1037, in _send_output
    self.send(msg)
  File "C:\Program Files\Python310\lib\http\client.py", line 975, in send
    self.connect()
  File "C:\Users\user\PycharmProjects\livelib-bot\venv\lib\site-packages\urllib3\connection.py", line 205, in connect
    conn = self._new_conn()
  File "C:\Users\user\PycharmProjects\livelib-bot\venv\lib\site-packages\urllib3\connection.py", line 186, in _new_conn
    raise NewConnectionError(
urllib3.exceptions.NewConnectionError: <urllib3.connection.HTTPConnection object at 0x00000211C9101BA0>: Failed to establish a new connection: [Errno 11001] getaddrinfo failed

During handling of the above exception, another exception occurred:

Traceback (most recent call last):
  File "C:\Users\user\PycharmProjects\livelib-bot\venv\lib\site-packages\requests\adapters.py", line 489, in send
    resp = conn.urlopen(
  File "C:\Users\user\PycharmProjects\livelib-bot\venv\lib\site-packages\urllib3\connectionpool.py", line 787, in urlopen
    retries = retries.increment(
  File "C:\Users\user\PycharmProjects\livelib-bot\venv\lib\site-packages\urllib3\util\retry.py", line 592, in increment
    raise MaxRetryError(_pool, url, error or ResponseError(cause))
urllib3.exceptions.MaxRetryError: HTTPConnectionPool(host='example4567.com', port=80): Max retries exceeded with url: / (Caused by NewConnectionError('<urllib3.connection.HTTPConnection object at 0x00000211C9101BA0>: Failed to establish a new connection: [Errno 11001] getaddrinfo failed'))

During handling of the above exception, another exception occurred:

Traceback (most recent call last):
  File "C:\Users\user\PycharmProjects\livelib-bot\livelib\webconnection.py", line 139, in _get_page
    result = requests.get(url, headers=headers)
  File "C:\Users\user\PycharmProjects\livelib-bot\venv\lib\site-packages\requests\api.py", line 73, in get
    return request("get", url, params=params, **kwargs)
  File "C:\Users\user\PycharmProjects\livelib-bot\venv\lib\site-packages\requests\api.py", line 59, in request
    return session.request(method=method, url=url, **kwargs)
  File "C:\Users\user\PycharmProjects\livelib-bot\venv\lib\site-packages\requests\sessions.py", line 587, in request
    resp = self.send(prep, **send_kwargs)
  File "C:\Users\user\PycharmProjects\livelib-bot\venv\lib\site-packages\requests\sessions.py", line 701, in send
    r = adapter.send(request, **kwargs)
  File "C:\Users\user\PycharmProjects\livelib-bot\venv\lib\site-packages\requests\adapters.py", line 565, in send
    raise ConnectionError(e, request=request)
requests.exceptions.ConnectionError: HTTPConnectionPool(host='example4567.com', port=80): Max retries exceeded with url: / (Caused by NewConnectionError('<urllib3.connection.HTTPConnection object at 0x00000211C9101BA0>: Failed to establish a new connection: [Errno 11001] getaddrinfo failed'))
Making request to http://www.livelib.ru
Starting new HTTP connection (1): www.livelib.ru:80
http://www.livelib.ru:80 "GET / HTTP/1.1" 302 138
Starting new HTTPS connection (1): www.livelib.ru:443
https://www.livelib.ru:443 "GET / HTTP/1.1" 200 None
Making request to http://www.yandex.com
Starting new HTTP connection (1): www.yandex.com:80
http://www.yandex.com:80 "GET / HTTP/1.1" 302 None
http://www.yandex.com:80 "GET /showcaptcha?cc=1&mt=5C5320E9B462F4737E543AA99837AE30CD7D621E109E0B66ED3BA41BC9371BF374792E3505AE27D5D354F2437A0AD6AE196021DB8B7FF07D31A4A9E2054406949B559D63D6393DA5189BCB972CF5F503E8A8FC8796DEC30CE9C6&retpath=aHR0cDovL3d3dy55YW5kZXguY29tLz8%2C_03325bfc427335a7d143da493e8c7883&t=2/1684924204/f41e661d443a6c73757704c71775f0f2&u=dd591de9-90eb139d-9df00034-4758985a&s=72b7038a0624524213e45fe86e022e61 HTTP/1.1" 200 13080
Making request to http://www.example.com
Starting new HTTP connection (1): www.example.com:80
http://www.example.com:80 "GET / HTTP/1.1" 200 648
Making request to http://example4567.com
Starting new HTTP connection (1): example4567.com:80
Can not open this page!
Traceback (most recent call last):
  File "C:\Users\user\PycharmProjects\livelib-bot\venv\lib\site-packages\urllib3\connection.py", line 174, in _new_conn
    conn = connection.create_connection(
  File "C:\Users\user\PycharmProjects\livelib-bot\venv\lib\site-packages\urllib3\util\connection.py", line 72, in create_connection
    for res in socket.getaddrinfo(host, port, family, socket.SOCK_STREAM):
  File "C:\Program Files\Python310\lib\socket.py", line 955, in getaddrinfo
    for res in _socket.getaddrinfo(host, port, family, type, proto, flags):
socket.gaierror: [Errno 11001] getaddrinfo failed

During handling of the above exception, another exception occurred:

Traceback (most recent call last):
  File "C:\Users\user\PycharmProjects\livelib-bot\venv\lib\site-packages\urllib3\connectionpool.py", line 703, in urlopen
    httplib_response = self._make_request(
  File "C:\Users\user\PycharmProjects\livelib-bot\venv\lib\site-packages\urllib3\connectionpool.py", line 398, in _make_request
    conn.request(method, url, **httplib_request_kw)
  File "C:\Users\user\PycharmProjects\livelib-bot\venv\lib\site-packages\urllib3\connection.py", line 244, in request
    super(HTTPConnection, self).request(method, url, body=body, headers=headers)
  File "C:\Program Files\Python310\lib\http\client.py", line 1282, in request
    self._send_request(method, url, body, headers, encode_chunked)
  File "C:\Program Files\Python310\lib\http\client.py", line 1328, in _send_request
    self.endheaders(body, encode_chunked=encode_chunked)
  File "C:\Program Files\Python310\lib\http\client.py", line 1277, in endheaders
    self._send_output(message_body, encode_chunked=encode_chunked)
  File "C:\Program Files\Python310\lib\http\client.py", line 1037, in _send_output
    self.send(msg)
  File "C:\Program Files\Python310\lib\http\client.py", line 975, in send
    self.connect()
  File "C:\Users\user\PycharmProjects\livelib-bot\venv\lib\site-packages\urllib3\connection.py", line 205, in connect
    conn = self._new_conn()
  File "C:\Users\user\PycharmProjects\livelib-bot\venv\lib\site-packages\urllib3\connection.py", line 186, in _new_conn
    raise NewConnectionError(
urllib3.exceptions.NewConnectionError: <urllib3.connection.HTTPConnection object at 0x00000211C91024D0>: Failed to establish a new connection: [Errno 11001] getaddrinfo failed

During handling of the above exception, another exception occurred:

Traceback (most recent call last):
  File "C:\Users\user\PycharmProjects\livelib-bot\venv\lib\site-packages\requests\adapters.py", line 489, in send
    resp = conn.urlopen(
  File "C:\Users\user\PycharmProjects\livelib-bot\venv\lib\site-packages\urllib3\connectionpool.py", line 787, in urlopen
    retries = retries.increment(
  File "C:\Users\user\PycharmProjects\livelib-bot\venv\lib\site-packages\urllib3\util\retry.py", line 592, in increment
    raise MaxRetryError(_pool, url, error or ResponseError(cause))
urllib3.exceptions.MaxRetryError: HTTPConnectionPool(host='example4567.com', port=80): Max retries exceeded with url: / (Caused by NewConnectionError('<urllib3.connection.HTTPConnection object at 0x00000211C91024D0>: Failed to establish a new connection: [Errno 11001] getaddrinfo failed'))

During handling of the above exception, another exception occurred:

Traceback (most recent call last):
  File "C:\Users\user\PycharmProjects\livelib-bot\livelib\webconnection.py", line 139, in _get_page
    result = requests.get(url, headers=headers)
  File "C:\Users\user\PycharmProjects\livelib-bot\venv\lib\site-packages\requests\api.py", line 73, in get
    return request("get", url, params=params, **kwargs)
  File "C:\Users\user\PycharmProjects\livelib-bot\venv\lib\site-packages\requests\api.py", line 59, in request
    return session.request(method=method, url=url, **kwargs)
  File "C:\Users\user\PycharmProjects\livelib-bot\venv\lib\site-packages\requests\sessions.py", line 587, in request
    resp = self.send(prep, **send_kwargs)
  File "C:\Users\user\PycharmProjects\livelib-bot\venv\lib\site-packages\requests\sessions.py", line 701, in send
    r = adapter.send(request, **kwargs)
  File "C:\Users\user\PycharmProjects\livelib-bot\venv\lib\site-packages\requests\adapters.py", line 565, in send
    raise ConnectionError(e, request=request)
requests.exceptions.ConnectionError: HTTPConnectionPool(host='example4567.com', port=80): Max retries exceeded with url: / (Caused by NewConnectionError('<urllib3.connection.HTTPConnection object at 0x00000211C91024D0>: Failed to establish a new connection: [Errno 11001] getaddrinfo failed'))
Can not get text from page! http://example4567.com
Traceback (most recent call last):
  File "C:\Users\user\PycharmProjects\livelib-bot\venv\lib\site-packages\urllib3\connection.py", line 174, in _new_conn
    conn = connection.create_connection(
  File "C:\Users\user\PycharmProjects\livelib-bot\venv\lib\site-packages\urllib3\util\connection.py", line 72, in create_connection
    for res in socket.getaddrinfo(host, port, family, socket.SOCK_STREAM):
  File "C:\Program Files\Python310\lib\socket.py", line 955, in getaddrinfo
    for res in _socket.getaddrinfo(host, port, family, type, proto, flags):
socket.gaierror: [Errno 11001] getaddrinfo failed

During handling of the above exception, another exception occurred:

Traceback (most recent call last):
  File "C:\Users\user\PycharmProjects\livelib-bot\venv\lib\site-packages\urllib3\connectionpool.py", line 703, in urlopen
    httplib_response = self._make_request(
  File "C:\Users\user\PycharmProjects\livelib-bot\venv\lib\site-packages\urllib3\connectionpool.py", line 398, in _make_request
    conn.request(method, url, **httplib_request_kw)
  File "C:\Users\user\PycharmProjects\livelib-bot\venv\lib\site-packages\urllib3\connection.py", line 244, in request
    super(HTTPConnection, self).request(method, url, body=body, headers=headers)
  File "C:\Program Files\Python310\lib\http\client.py", line 1282, in request
    self._send_request(method, url, body, headers, encode_chunked)
  File "C:\Program Files\Python310\lib\http\client.py", line 1328, in _send_request
    self.endheaders(body, encode_chunked=encode_chunked)
  File "C:\Program Files\Python310\lib\http\client.py", line 1277, in endheaders
    self._send_output(message_body, encode_chunked=encode_chunked)
  File "C:\Program Files\Python310\lib\http\client.py", line 1037, in _send_output
    self.send(msg)
  File "C:\Program Files\Python310\lib\http\client.py", line 975, in send
    self.connect()
  File "C:\Users\user\PycharmProjects\livelib-bot\venv\lib\site-packages\urllib3\connection.py", line 205, in connect
    conn = self._new_conn()
  File "C:\Users\user\PycharmProjects\livelib-bot\venv\lib\site-packages\urllib3\connection.py", line 186, in _new_conn
    raise NewConnectionError(
urllib3.exceptions.NewConnectionError: <urllib3.connection.HTTPConnection object at 0x00000211C91024D0>: Failed to establish a new connection: [Errno 11001] getaddrinfo failed

During handling of the above exception, another exception occurred:

Traceback (most recent call last):
  File "C:\Users\user\PycharmProjects\livelib-bot\venv\lib\site-packages\requests\adapters.py", line 489, in send
    resp = conn.urlopen(
  File "C:\Users\user\PycharmProjects\livelib-bot\venv\lib\site-packages\urllib3\connectionpool.py", line 787, in urlopen
    retries = retries.increment(
  File "C:\Users\user\PycharmProjects\livelib-bot\venv\lib\site-packages\urllib3\util\retry.py", line 592, in increment
    raise MaxRetryError(_pool, url, error or ResponseError(cause))
urllib3.exceptions.MaxRetryError: HTTPConnectionPool(host='example4567.com', port=80): Max retries exceeded with url: / (Caused by NewConnectionError('<urllib3.connection.HTTPConnection object at 0x00000211C91024D0>: Failed to establish a new connection: [Errno 11001] getaddrinfo failed'))

During handling of the above exception, another exception occurred:

Traceback (most recent call last):
  File "C:\Users\user\PycharmProjects\livelib-bot\livelib\webconnection.py", line 168, in get_page_text
    page = self._get_page(url)
  File "C:\Users\user\PycharmProjects\livelib-bot\livelib\webconnection.py", line 139, in _get_page
    result = requests.get(url, headers=headers)
  File "C:\Users\user\PycharmProjects\livelib-bot\venv\lib\site-packages\requests\api.py", line 73, in get
    return request("get", url, params=params, **kwargs)
  File "C:\Users\user\PycharmProjects\livelib-bot\venv\lib\site-packages\requests\api.py", line 59, in request
    return session.request(method=method, url=url, **kwargs)
  File "C:\Users\user\PycharmProjects\livelib-bot\venv\lib\site-packages\requests\sessions.py", line 587, in request
    resp = self.send(prep, **send_kwargs)
  File "C:\Users\user\PycharmProjects\livelib-bot\venv\lib\site-packages\requests\sessions.py", line 701, in send
    r = adapter.send(request, **kwargs)
  File "C:\Users\user\PycharmProjects\livelib-bot\venv\lib\site-packages\requests\adapters.py", line 565, in send
    raise ConnectionError(e, request=request)
requests.exceptions.ConnectionError: HTTPConnectionPool(host='example4567.com', port=80): Max retries exceeded with url: / (Caused by NewConnectionError('<urllib3.connection.HTTPConnection object at 0x00000211C91024D0>: Failed to establish a new connection: [Errno 11001] getaddrinfo failed'))
Making request to http://www.livelib.ru
Starting new HTTP connection (1): www.livelib.ru:80
http://www.livelib.ru:80 "GET / HTTP/1.1" 302 138
Starting new HTTPS connection (1): www.livelib.ru:443
https://www.livelib.ru:443 "GET / HTTP/1.1" 200 None
Making request to http://www.yandex.com
Starting new HTTP connection (1): www.yandex.com:80
http://www.yandex.com:80 "GET / HTTP/1.1" 302 None
http://www.yandex.com:80 "GET /showcaptcha?cc=1&mt=212DAD62E266DB9970CE7E2797A031823AEF4961144032BB35479D254C9D4AFAF559DD994F56903E94A583C55758491095732E9604219A60E6D05F4F43A3EC3C552041570D64A9CC237A07CEBAE9541BBC1C153D2EB5347AA27B&retpath=aHR0cDovL3d3dy55YW5kZXguY29tLz8%2C_03325bfc427335a7d143da493e8c7883&t=2/1684924204/d7a0b627e26b05624114c4028a721067&u=2c85c17f-b6c18300-43784481-f1b49aeb&s=8ee354c3319a4ac1f5bc60fafcd673d6 HTTP/1.1" 200 13084
Dir web_with_cache_test is found? False
Create dir web_with_cache_test
Dir web_with_cache_test/ is found? True
Create file <_io.TextIOWrapper name='web_with_cache_test/index.html' mode='x' encoding='utf-8'> 
Already have web_with_cache_test/index.html
Dir web_with_cache_test is found? True
Dir web_with_cache_test/foo is found? False
Create dir web_with_cache_test/foo
Dir web_with_cache_test/foo/ is found? True
Create file <_io.TextIOWrapper name='web_with_cache_test/foo/bar.html' mode='x' encoding='utf-8'> 
Already have web_with_cache_test/foo/bar.html
Already have web_with_cache_test/foo/bar.html
Dir web_with_cache_test is found? True
Dir web_with_cache_test/foo is found? True
Dir web_with_cache_test/foo/ is found? True
Create file <_io.TextIOWrapper name='web_with_cache_test/foo/2.html' mode='x' encoding='utf-8'> 
Already have web_with_cache_test/foo/2.html
Dir web_with_cache_test is found? True
Dir web_with_cache_test/foo is found? True
Dir web_with_cache_test/foo/bar is found? False
Create dir web_with_cache_test/foo/bar
Dir web_with_cache_test/foo/bar/ is found? True
Create file <_io.TextIOWrapper name='web_with_cache_test/foo/bar/index.html' mode='x' encoding='utf-8'> 
Already have web_with_cache_test/foo/bar/index.html
Dir web_with_cache_test is found? True
Dir web_with_cache_test/foo is found? True
Dir web_with_cache_test/foo/bar is found? True
Dir web_with_cache_test/foo/bar/ is found? True
Create file <_io.TextIOWrapper name='web_with_cache_test/foo/bar/1.html' mode='x' encoding='utf-8'> 
Already have web_with_cache_test/foo/bar/1.html
Dir web_with_cache_test is found? True
Dir web_with_cache_test/ is found? True
Create file <_io.TextIOWrapper name='web_with_cache_test/1.html' mode='x' encoding='utf-8'> 
Already have web_with_cache_test/1.html
Dir web_with_cache_test is found? True
Dir web_with_cache_test/foo is found? True
Dir web_with_cache_test/foo/ is found? True
Create file <_io.TextIOWrapper name='web_with_cache_test/foo/~12.html' mode='x' encoding='utf-8'> 
Already have web_with_cache_test/foo/~12.html
Cleaning dirs and files after testing
Cleaning dirs and files after testing
