2023-05-24--13-29 : starting to run unit tests from test_webconnection.log ... 
Making request to http://www.example.com
Starting new HTTP connection (1): www.example.com:80
http://www.example.com:80 "GET / HTTP/1.1" 200 648
Making request to http://example4567.com
Starting new HTTP connection (1): example4567.com:80
Can not open this page!
Traceback (most recent call last):
  File "C:\Users\user\PycharmProjects\livelib-bot\venv\lib\site-packages\urllib3\connection.py", line 174, in _new_conn
    conn = connection.create_connection(
  File "C:\Users\user\PycharmProjects\livelib-bot\venv\lib\site-packages\urllib3\util\connection.py", line 72, in create_connection
    for res in socket.getaddrinfo(host, port, family, socket.SOCK_STREAM):
  File "C:\Program Files\Python310\lib\socket.py", line 955, in getaddrinfo
    for res in _socket.getaddrinfo(host, port, family, type, proto, flags):
socket.gaierror: [Errno 11001] getaddrinfo failed

During handling of the above exception, another exception occurred:

Traceback (most recent call last):
  File "C:\Users\user\PycharmProjects\livelib-bot\venv\lib\site-packages\urllib3\connectionpool.py", line 703, in urlopen
    httplib_response = self._make_request(
  File "C:\Users\user\PycharmProjects\livelib-bot\venv\lib\site-packages\urllib3\connectionpool.py", line 398, in _make_request
    conn.request(method, url, **httplib_request_kw)
  File "C:\Users\user\PycharmProjects\livelib-bot\venv\lib\site-packages\urllib3\connection.py", line 244, in request
    super(HTTPConnection, self).request(method, url, body=body, headers=headers)
  File "C:\Program Files\Python310\lib\http\client.py", line 1282, in request
    self._send_request(method, url, body, headers, encode_chunked)
  File "C:\Program Files\Python310\lib\http\client.py", line 1328, in _send_request
    self.endheaders(body, encode_chunked=encode_chunked)
  File "C:\Program Files\Python310\lib\http\client.py", line 1277, in endheaders
    self._send_output(message_body, encode_chunked=encode_chunked)
  File "C:\Program Files\Python310\lib\http\client.py", line 1037, in _send_output
    self.send(msg)
  File "C:\Program Files\Python310\lib\http\client.py", line 975, in send
    self.connect()
  File "C:\Users\user\PycharmProjects\livelib-bot\venv\lib\site-packages\urllib3\connection.py", line 205, in connect
    conn = self._new_conn()
  File "C:\Users\user\PycharmProjects\livelib-bot\venv\lib\site-packages\urllib3\connection.py", line 186, in _new_conn
    raise NewConnectionError(
urllib3.exceptions.NewConnectionError: <urllib3.connection.HTTPConnection object at 0x00000211CA27F250>: Failed to establish a new connection: [Errno 11001] getaddrinfo failed

During handling of the above exception, another exception occurred:

Traceback (most recent call last):
  File "C:\Users\user\PycharmProjects\livelib-bot\venv\lib\site-packages\requests\adapters.py", line 489, in send
    resp = conn.urlopen(
  File "C:\Users\user\PycharmProjects\livelib-bot\venv\lib\site-packages\urllib3\connectionpool.py", line 787, in urlopen
    retries = retries.increment(
  File "C:\Users\user\PycharmProjects\livelib-bot\venv\lib\site-packages\urllib3\util\retry.py", line 592, in increment
    raise MaxRetryError(_pool, url, error or ResponseError(cause))
urllib3.exceptions.MaxRetryError: HTTPConnectionPool(host='example4567.com', port=80): Max retries exceeded with url: / (Caused by NewConnectionError('<urllib3.connection.HTTPConnection object at 0x00000211CA27F250>: Failed to establish a new connection: [Errno 11001] getaddrinfo failed'))

During handling of the above exception, another exception occurred:

Traceback (most recent call last):
  File "C:\Users\user\PycharmProjects\livelib-bot\livelib\webconnection.py", line 139, in _get_page
    result = requests.get(url, headers=headers)
  File "C:\Users\user\PycharmProjects\livelib-bot\venv\lib\site-packages\requests\api.py", line 73, in get
    return request("get", url, params=params, **kwargs)
  File "C:\Users\user\PycharmProjects\livelib-bot\venv\lib\site-packages\requests\api.py", line 59, in request
    return session.request(method=method, url=url, **kwargs)
  File "C:\Users\user\PycharmProjects\livelib-bot\venv\lib\site-packages\requests\sessions.py", line 587, in request
    resp = self.send(prep, **send_kwargs)
  File "C:\Users\user\PycharmProjects\livelib-bot\venv\lib\site-packages\requests\sessions.py", line 701, in send
    r = adapter.send(request, **kwargs)
  File "C:\Users\user\PycharmProjects\livelib-bot\venv\lib\site-packages\requests\adapters.py", line 565, in send
    raise ConnectionError(e, request=request)
requests.exceptions.ConnectionError: HTTPConnectionPool(host='example4567.com', port=80): Max retries exceeded with url: / (Caused by NewConnectionError('<urllib3.connection.HTTPConnection object at 0x00000211CA27F250>: Failed to establish a new connection: [Errno 11001] getaddrinfo failed'))
Can not get text from page! http://example4567.com
Traceback (most recent call last):
  File "C:\Users\user\PycharmProjects\livelib-bot\venv\lib\site-packages\urllib3\connection.py", line 174, in _new_conn
    conn = connection.create_connection(
  File "C:\Users\user\PycharmProjects\livelib-bot\venv\lib\site-packages\urllib3\util\connection.py", line 72, in create_connection
    for res in socket.getaddrinfo(host, port, family, socket.SOCK_STREAM):
  File "C:\Program Files\Python310\lib\socket.py", line 955, in getaddrinfo
    for res in _socket.getaddrinfo(host, port, family, type, proto, flags):
socket.gaierror: [Errno 11001] getaddrinfo failed

During handling of the above exception, another exception occurred:

Traceback (most recent call last):
  File "C:\Users\user\PycharmProjects\livelib-bot\venv\lib\site-packages\urllib3\connectionpool.py", line 703, in urlopen
    httplib_response = self._make_request(
  File "C:\Users\user\PycharmProjects\livelib-bot\venv\lib\site-packages\urllib3\connectionpool.py", line 398, in _make_request
    conn.request(method, url, **httplib_request_kw)
  File "C:\Users\user\PycharmProjects\livelib-bot\venv\lib\site-packages\urllib3\connection.py", line 244, in request
    super(HTTPConnection, self).request(method, url, body=body, headers=headers)
  File "C:\Program Files\Python310\lib\http\client.py", line 1282, in request
    self._send_request(method, url, body, headers, encode_chunked)
  File "C:\Program Files\Python310\lib\http\client.py", line 1328, in _send_request
    self.endheaders(body, encode_chunked=encode_chunked)
  File "C:\Program Files\Python310\lib\http\client.py", line 1277, in endheaders
    self._send_output(message_body, encode_chunked=encode_chunked)
  File "C:\Program Files\Python310\lib\http\client.py", line 1037, in _send_output
    self.send(msg)
  File "C:\Program Files\Python310\lib\http\client.py", line 975, in send
    self.connect()
  File "C:\Users\user\PycharmProjects\livelib-bot\venv\lib\site-packages\urllib3\connection.py", line 205, in connect
    conn = self._new_conn()
  File "C:\Users\user\PycharmProjects\livelib-bot\venv\lib\site-packages\urllib3\connection.py", line 186, in _new_conn
    raise NewConnectionError(
urllib3.exceptions.NewConnectionError: <urllib3.connection.HTTPConnection object at 0x00000211CA27F250>: Failed to establish a new connection: [Errno 11001] getaddrinfo failed

During handling of the above exception, another exception occurred:

Traceback (most recent call last):
  File "C:\Users\user\PycharmProjects\livelib-bot\venv\lib\site-packages\requests\adapters.py", line 489, in send
    resp = conn.urlopen(
  File "C:\Users\user\PycharmProjects\livelib-bot\venv\lib\site-packages\urllib3\connectionpool.py", line 787, in urlopen
    retries = retries.increment(
  File "C:\Users\user\PycharmProjects\livelib-bot\venv\lib\site-packages\urllib3\util\retry.py", line 592, in increment
    raise MaxRetryError(_pool, url, error or ResponseError(cause))
urllib3.exceptions.MaxRetryError: HTTPConnectionPool(host='example4567.com', port=80): Max retries exceeded with url: / (Caused by NewConnectionError('<urllib3.connection.HTTPConnection object at 0x00000211CA27F250>: Failed to establish a new connection: [Errno 11001] getaddrinfo failed'))

During handling of the above exception, another exception occurred:

Traceback (most recent call last):
  File "C:\Users\user\PycharmProjects\livelib-bot\livelib\webconnection.py", line 168, in get_page_text
    page = self._get_page(url)
  File "C:\Users\user\PycharmProjects\livelib-bot\livelib\webconnection.py", line 139, in _get_page
    result = requests.get(url, headers=headers)
  File "C:\Users\user\PycharmProjects\livelib-bot\venv\lib\site-packages\requests\api.py", line 73, in get
    return request("get", url, params=params, **kwargs)
  File "C:\Users\user\PycharmProjects\livelib-bot\venv\lib\site-packages\requests\api.py", line 59, in request
    return session.request(method=method, url=url, **kwargs)
  File "C:\Users\user\PycharmProjects\livelib-bot\venv\lib\site-packages\requests\sessions.py", line 587, in request
    resp = self.send(prep, **send_kwargs)
  File "C:\Users\user\PycharmProjects\livelib-bot\venv\lib\site-packages\requests\sessions.py", line 701, in send
    r = adapter.send(request, **kwargs)
  File "C:\Users\user\PycharmProjects\livelib-bot\venv\lib\site-packages\requests\adapters.py", line 565, in send
    raise ConnectionError(e, request=request)
requests.exceptions.ConnectionError: HTTPConnectionPool(host='example4567.com', port=80): Max retries exceeded with url: / (Caused by NewConnectionError('<urllib3.connection.HTTPConnection object at 0x00000211CA27F250>: Failed to establish a new connection: [Errno 11001] getaddrinfo failed'))
Can not get BS object from http://example4567.com
Traceback (most recent call last):
  File "C:\Users\user\PycharmProjects\livelib-bot\venv\lib\site-packages\urllib3\connection.py", line 174, in _new_conn
    conn = connection.create_connection(
  File "C:\Users\user\PycharmProjects\livelib-bot\venv\lib\site-packages\urllib3\util\connection.py", line 72, in create_connection
    for res in socket.getaddrinfo(host, port, family, socket.SOCK_STREAM):
  File "C:\Program Files\Python310\lib\socket.py", line 955, in getaddrinfo
    for res in _socket.getaddrinfo(host, port, family, type, proto, flags):
socket.gaierror: [Errno 11001] getaddrinfo failed

During handling of the above exception, another exception occurred:

Traceback (most recent call last):
  File "C:\Users\user\PycharmProjects\livelib-bot\venv\lib\site-packages\urllib3\connectionpool.py", line 703, in urlopen
    httplib_response = self._make_request(
  File "C:\Users\user\PycharmProjects\livelib-bot\venv\lib\site-packages\urllib3\connectionpool.py", line 398, in _make_request
    conn.request(method, url, **httplib_request_kw)
  File "C:\Users\user\PycharmProjects\livelib-bot\venv\lib\site-packages\urllib3\connection.py", line 244, in request
    super(HTTPConnection, self).request(method, url, body=body, headers=headers)
  File "C:\Program Files\Python310\lib\http\client.py", line 1282, in request
    self._send_request(method, url, body, headers, encode_chunked)
  File "C:\Program Files\Python310\lib\http\client.py", line 1328, in _send_request
    self.endheaders(body, encode_chunked=encode_chunked)
  File "C:\Program Files\Python310\lib\http\client.py", line 1277, in endheaders
    self._send_output(message_body, encode_chunked=encode_chunked)
  File "C:\Program Files\Python310\lib\http\client.py", line 1037, in _send_output
    self.send(msg)
  File "C:\Program Files\Python310\lib\http\client.py", line 975, in send
    self.connect()
  File "C:\Users\user\PycharmProjects\livelib-bot\venv\lib\site-packages\urllib3\connection.py", line 205, in connect
    conn = self._new_conn()
  File "C:\Users\user\PycharmProjects\livelib-bot\venv\lib\site-packages\urllib3\connection.py", line 186, in _new_conn
    raise NewConnectionError(
urllib3.exceptions.NewConnectionError: <urllib3.connection.HTTPConnection object at 0x00000211CA27F250>: Failed to establish a new connection: [Errno 11001] getaddrinfo failed

During handling of the above exception, another exception occurred:

Traceback (most recent call last):
  File "C:\Users\user\PycharmProjects\livelib-bot\venv\lib\site-packages\requests\adapters.py", line 489, in send
    resp = conn.urlopen(
  File "C:\Users\user\PycharmProjects\livelib-bot\venv\lib\site-packages\urllib3\connectionpool.py", line 787, in urlopen
    retries = retries.increment(
  File "C:\Users\user\PycharmProjects\livelib-bot\venv\lib\site-packages\urllib3\util\retry.py", line 592, in increment
    raise MaxRetryError(_pool, url, error or ResponseError(cause))
urllib3.exceptions.MaxRetryError: HTTPConnectionPool(host='example4567.com', port=80): Max retries exceeded with url: / (Caused by NewConnectionError('<urllib3.connection.HTTPConnection object at 0x00000211CA27F250>: Failed to establish a new connection: [Errno 11001] getaddrinfo failed'))

During handling of the above exception, another exception occurred:

Traceback (most recent call last):
  File "C:\Users\user\PycharmProjects\livelib-bot\livelib\webconnection.py", line 52, in _get_page_bs
    result = bs4.BeautifulSoup(self.get_page_text(url), features='lxml')
  File "C:\Users\user\PycharmProjects\livelib-bot\livelib\webconnection.py", line 168, in get_page_text
    page = self._get_page(url)
  File "C:\Users\user\PycharmProjects\livelib-bot\livelib\webconnection.py", line 139, in _get_page
    result = requests.get(url, headers=headers)
  File "C:\Users\user\PycharmProjects\livelib-bot\venv\lib\site-packages\requests\api.py", line 73, in get
    return request("get", url, params=params, **kwargs)
  File "C:\Users\user\PycharmProjects\livelib-bot\venv\lib\site-packages\requests\api.py", line 59, in request
    return session.request(method=method, url=url, **kwargs)
  File "C:\Users\user\PycharmProjects\livelib-bot\venv\lib\site-packages\requests\sessions.py", line 587, in request
    resp = self.send(prep, **send_kwargs)
  File "C:\Users\user\PycharmProjects\livelib-bot\venv\lib\site-packages\requests\sessions.py", line 701, in send
    r = adapter.send(request, **kwargs)
  File "C:\Users\user\PycharmProjects\livelib-bot\venv\lib\site-packages\requests\adapters.py", line 565, in send
    raise ConnectionError(e, request=request)
requests.exceptions.ConnectionError: HTTPConnectionPool(host='example4567.com', port=80): Max retries exceeded with url: / (Caused by NewConnectionError('<urllib3.connection.HTTPConnection object at 0x00000211CA27F250>: Failed to establish a new connection: [Errno 11001] getaddrinfo failed'))
Making request to http://www.livelib.ru
Starting new HTTP connection (1): www.livelib.ru:80
http://www.livelib.ru:80 "GET / HTTP/1.1" 302 138
Starting new HTTPS connection (1): www.livelib.ru:443
https://www.livelib.ru:443 "GET / HTTP/1.1" 200 None
Making request to http://www.yandex.com
Starting new HTTP connection (1): www.yandex.com:80
http://www.yandex.com:80 "GET / HTTP/1.1" 302 None
Starting new HTTPS connection (1): yandex.com:443
https://yandex.com:443 "GET / HTTP/1.1" 200 None
Making request to http://www.example.com
Starting new HTTP connection (1): www.example.com:80
http://www.example.com:80 "GET / HTTP/1.1" 200 648
Making request to http://example4567.com
Starting new HTTP connection (1): example4567.com:80
Can not open this page!
Traceback (most recent call last):
  File "C:\Users\user\PycharmProjects\livelib-bot\venv\lib\site-packages\urllib3\connection.py", line 174, in _new_conn
    conn = connection.create_connection(
  File "C:\Users\user\PycharmProjects\livelib-bot\venv\lib\site-packages\urllib3\util\connection.py", line 72, in create_connection
    for res in socket.getaddrinfo(host, port, family, socket.SOCK_STREAM):
  File "C:\Program Files\Python310\lib\socket.py", line 955, in getaddrinfo
    for res in _socket.getaddrinfo(host, port, family, type, proto, flags):
socket.gaierror: [Errno 11001] getaddrinfo failed

During handling of the above exception, another exception occurred:

Traceback (most recent call last):
  File "C:\Users\user\PycharmProjects\livelib-bot\venv\lib\site-packages\urllib3\connectionpool.py", line 703, in urlopen
    httplib_response = self._make_request(
  File "C:\Users\user\PycharmProjects\livelib-bot\venv\lib\site-packages\urllib3\connectionpool.py", line 398, in _make_request
    conn.request(method, url, **httplib_request_kw)
  File "C:\Users\user\PycharmProjects\livelib-bot\venv\lib\site-packages\urllib3\connection.py", line 244, in request
    super(HTTPConnection, self).request(method, url, body=body, headers=headers)
  File "C:\Program Files\Python310\lib\http\client.py", line 1282, in request
    self._send_request(method, url, body, headers, encode_chunked)
  File "C:\Program Files\Python310\lib\http\client.py", line 1328, in _send_request
    self.endheaders(body, encode_chunked=encode_chunked)
  File "C:\Program Files\Python310\lib\http\client.py", line 1277, in endheaders
    self._send_output(message_body, encode_chunked=encode_chunked)
  File "C:\Program Files\Python310\lib\http\client.py", line 1037, in _send_output
    self.send(msg)
  File "C:\Program Files\Python310\lib\http\client.py", line 975, in send
    self.connect()
  File "C:\Users\user\PycharmProjects\livelib-bot\venv\lib\site-packages\urllib3\connection.py", line 205, in connect
    conn = self._new_conn()
  File "C:\Users\user\PycharmProjects\livelib-bot\venv\lib\site-packages\urllib3\connection.py", line 186, in _new_conn
    raise NewConnectionError(
urllib3.exceptions.NewConnectionError: <urllib3.connection.HTTPConnection object at 0x00000211C9DAF370>: Failed to establish a new connection: [Errno 11001] getaddrinfo failed

During handling of the above exception, another exception occurred:

Traceback (most recent call last):
  File "C:\Users\user\PycharmProjects\livelib-bot\venv\lib\site-packages\requests\adapters.py", line 489, in send
    resp = conn.urlopen(
  File "C:\Users\user\PycharmProjects\livelib-bot\venv\lib\site-packages\urllib3\connectionpool.py", line 787, in urlopen
    retries = retries.increment(
  File "C:\Users\user\PycharmProjects\livelib-bot\venv\lib\site-packages\urllib3\util\retry.py", line 592, in increment
    raise MaxRetryError(_pool, url, error or ResponseError(cause))
urllib3.exceptions.MaxRetryError: HTTPConnectionPool(host='example4567.com', port=80): Max retries exceeded with url: / (Caused by NewConnectionError('<urllib3.connection.HTTPConnection object at 0x00000211C9DAF370>: Failed to establish a new connection: [Errno 11001] getaddrinfo failed'))

During handling of the above exception, another exception occurred:

Traceback (most recent call last):
  File "C:\Users\user\PycharmProjects\livelib-bot\livelib\webconnection.py", line 139, in _get_page
    result = requests.get(url, headers=headers)
  File "C:\Users\user\PycharmProjects\livelib-bot\venv\lib\site-packages\requests\api.py", line 73, in get
    return request("get", url, params=params, **kwargs)
  File "C:\Users\user\PycharmProjects\livelib-bot\venv\lib\site-packages\requests\api.py", line 59, in request
    return session.request(method=method, url=url, **kwargs)
  File "C:\Users\user\PycharmProjects\livelib-bot\venv\lib\site-packages\requests\sessions.py", line 587, in request
    resp = self.send(prep, **send_kwargs)
  File "C:\Users\user\PycharmProjects\livelib-bot\venv\lib\site-packages\requests\sessions.py", line 701, in send
    r = adapter.send(request, **kwargs)
  File "C:\Users\user\PycharmProjects\livelib-bot\venv\lib\site-packages\requests\adapters.py", line 565, in send
    raise ConnectionError(e, request=request)
requests.exceptions.ConnectionError: HTTPConnectionPool(host='example4567.com', port=80): Max retries exceeded with url: / (Caused by NewConnectionError('<urllib3.connection.HTTPConnection object at 0x00000211C9DAF370>: Failed to establish a new connection: [Errno 11001] getaddrinfo failed'))
Making request to http://www.livelib.ru
Starting new HTTP connection (1): www.livelib.ru:80
http://www.livelib.ru:80 "GET / HTTP/1.1" 302 138
Starting new HTTPS connection (1): www.livelib.ru:443
https://www.livelib.ru:443 "GET / HTTP/1.1" 200 None
Making request to http://www.yandex.com
Starting new HTTP connection (1): www.yandex.com:80
http://www.yandex.com:80 "GET / HTTP/1.1" 302 None
http://www.yandex.com:80 "GET /showcaptcha?cc=1&mt=00493F763D2DBD17FB9B71D4EFBE28624EE8074BDADE2371A98C342E1231FC63FE1F64D02555C4C28B751D498A53AB1935A3FF5532827162DE64F252020A4BED249634AD33B5A8E335299EEA77E6D2F386D5A704442D9D1BC35C&retpath=aHR0cDovL3d3dy55YW5kZXguY29tLz8%2C_03325bfc427335a7d143da493e8c7883&t=2/1684924201/133f311cfe229308718c3bcf584728a6&u=1b7f8c59-f200c4b9-fff01d1e-2738fe95&s=10c34d4ea03353d9736661cea05eb658 HTTP/1.1" 200 13083
Making request to http://www.example.com
Starting new HTTP connection (1): www.example.com:80
http://www.example.com:80 "GET / HTTP/1.1" 200 648
Making request to http://example4567.com
Starting new HTTP connection (1): example4567.com:80
Can not open this page!
Traceback (most recent call last):
  File "C:\Users\user\PycharmProjects\livelib-bot\venv\lib\site-packages\urllib3\connection.py", line 174, in _new_conn
    conn = connection.create_connection(
  File "C:\Users\user\PycharmProjects\livelib-bot\venv\lib\site-packages\urllib3\util\connection.py", line 72, in create_connection
    for res in socket.getaddrinfo(host, port, family, socket.SOCK_STREAM):
  File "C:\Program Files\Python310\lib\socket.py", line 955, in getaddrinfo
    for res in _socket.getaddrinfo(host, port, family, type, proto, flags):
socket.gaierror: [Errno 11001] getaddrinfo failed

During handling of the above exception, another exception occurred:

Traceback (most recent call last):
  File "C:\Users\user\PycharmProjects\livelib-bot\venv\lib\site-packages\urllib3\connectionpool.py", line 703, in urlopen
    httplib_response = self._make_request(
  File "C:\Users\user\PycharmProjects\livelib-bot\venv\lib\site-packages\urllib3\connectionpool.py", line 398, in _make_request
    conn.request(method, url, **httplib_request_kw)
  File "C:\Users\user\PycharmProjects\livelib-bot\venv\lib\site-packages\urllib3\connection.py", line 244, in request
    super(HTTPConnection, self).request(method, url, body=body, headers=headers)
  File "C:\Program Files\Python310\lib\http\client.py", line 1282, in request
    self._send_request(method, url, body, headers, encode_chunked)
  File "C:\Program Files\Python310\lib\http\client.py", line 1328, in _send_request
    self.endheaders(body, encode_chunked=encode_chunked)
  File "C:\Program Files\Python310\lib\http\client.py", line 1277, in endheaders
    self._send_output(message_body, encode_chunked=encode_chunked)
  File "C:\Program Files\Python310\lib\http\client.py", line 1037, in _send_output
    self.send(msg)
  File "C:\Program Files\Python310\lib\http\client.py", line 975, in send
    self.connect()
  File "C:\Users\user\PycharmProjects\livelib-bot\venv\lib\site-packages\urllib3\connection.py", line 205, in connect
    conn = self._new_conn()
  File "C:\Users\user\PycharmProjects\livelib-bot\venv\lib\site-packages\urllib3\connection.py", line 186, in _new_conn
    raise NewConnectionError(
urllib3.exceptions.NewConnectionError: <urllib3.connection.HTTPConnection object at 0x00000211C9D68040>: Failed to establish a new connection: [Errno 11001] getaddrinfo failed

During handling of the above exception, another exception occurred:

Traceback (most recent call last):
  File "C:\Users\user\PycharmProjects\livelib-bot\venv\lib\site-packages\requests\adapters.py", line 489, in send
    resp = conn.urlopen(
  File "C:\Users\user\PycharmProjects\livelib-bot\venv\lib\site-packages\urllib3\connectionpool.py", line 787, in urlopen
    retries = retries.increment(
  File "C:\Users\user\PycharmProjects\livelib-bot\venv\lib\site-packages\urllib3\util\retry.py", line 592, in increment
    raise MaxRetryError(_pool, url, error or ResponseError(cause))
urllib3.exceptions.MaxRetryError: HTTPConnectionPool(host='example4567.com', port=80): Max retries exceeded with url: / (Caused by NewConnectionError('<urllib3.connection.HTTPConnection object at 0x00000211C9D68040>: Failed to establish a new connection: [Errno 11001] getaddrinfo failed'))

During handling of the above exception, another exception occurred:

Traceback (most recent call last):
  File "C:\Users\user\PycharmProjects\livelib-bot\livelib\webconnection.py", line 139, in _get_page
    result = requests.get(url, headers=headers)
  File "C:\Users\user\PycharmProjects\livelib-bot\venv\lib\site-packages\requests\api.py", line 73, in get
    return request("get", url, params=params, **kwargs)
  File "C:\Users\user\PycharmProjects\livelib-bot\venv\lib\site-packages\requests\api.py", line 59, in request
    return session.request(method=method, url=url, **kwargs)
  File "C:\Users\user\PycharmProjects\livelib-bot\venv\lib\site-packages\requests\sessions.py", line 587, in request
    resp = self.send(prep, **send_kwargs)
  File "C:\Users\user\PycharmProjects\livelib-bot\venv\lib\site-packages\requests\sessions.py", line 701, in send
    r = adapter.send(request, **kwargs)
  File "C:\Users\user\PycharmProjects\livelib-bot\venv\lib\site-packages\requests\adapters.py", line 565, in send
    raise ConnectionError(e, request=request)
requests.exceptions.ConnectionError: HTTPConnectionPool(host='example4567.com', port=80): Max retries exceeded with url: / (Caused by NewConnectionError('<urllib3.connection.HTTPConnection object at 0x00000211C9D68040>: Failed to establish a new connection: [Errno 11001] getaddrinfo failed'))
Can not get text from page! http://example4567.com
Traceback (most recent call last):
  File "C:\Users\user\PycharmProjects\livelib-bot\venv\lib\site-packages\urllib3\connection.py", line 174, in _new_conn
    conn = connection.create_connection(
  File "C:\Users\user\PycharmProjects\livelib-bot\venv\lib\site-packages\urllib3\util\connection.py", line 72, in create_connection
    for res in socket.getaddrinfo(host, port, family, socket.SOCK_STREAM):
  File "C:\Program Files\Python310\lib\socket.py", line 955, in getaddrinfo
    for res in _socket.getaddrinfo(host, port, family, type, proto, flags):
socket.gaierror: [Errno 11001] getaddrinfo failed

During handling of the above exception, another exception occurred:

Traceback (most recent call last):
  File "C:\Users\user\PycharmProjects\livelib-bot\venv\lib\site-packages\urllib3\connectionpool.py", line 703, in urlopen
    httplib_response = self._make_request(
  File "C:\Users\user\PycharmProjects\livelib-bot\venv\lib\site-packages\urllib3\connectionpool.py", line 398, in _make_request
    conn.request(method, url, **httplib_request_kw)
  File "C:\Users\user\PycharmProjects\livelib-bot\venv\lib\site-packages\urllib3\connection.py", line 244, in request
    super(HTTPConnection, self).request(method, url, body=body, headers=headers)
  File "C:\Program Files\Python310\lib\http\client.py", line 1282, in request
    self._send_request(method, url, body, headers, encode_chunked)
  File "C:\Program Files\Python310\lib\http\client.py", line 1328, in _send_request
    self.endheaders(body, encode_chunked=encode_chunked)
  File "C:\Program Files\Python310\lib\http\client.py", line 1277, in endheaders
    self._send_output(message_body, encode_chunked=encode_chunked)
  File "C:\Program Files\Python310\lib\http\client.py", line 1037, in _send_output
    self.send(msg)
  File "C:\Program Files\Python310\lib\http\client.py", line 975, in send
    self.connect()
  File "C:\Users\user\PycharmProjects\livelib-bot\venv\lib\site-packages\urllib3\connection.py", line 205, in connect
    conn = self._new_conn()
  File "C:\Users\user\PycharmProjects\livelib-bot\venv\lib\site-packages\urllib3\connection.py", line 186, in _new_conn
    raise NewConnectionError(
urllib3.exceptions.NewConnectionError: <urllib3.connection.HTTPConnection object at 0x00000211C9D68040>: Failed to establish a new connection: [Errno 11001] getaddrinfo failed

During handling of the above exception, another exception occurred:

Traceback (most recent call last):
  File "C:\Users\user\PycharmProjects\livelib-bot\venv\lib\site-packages\requests\adapters.py", line 489, in send
    resp = conn.urlopen(
  File "C:\Users\user\PycharmProjects\livelib-bot\venv\lib\site-packages\urllib3\connectionpool.py", line 787, in urlopen
    retries = retries.increment(
  File "C:\Users\user\PycharmProjects\livelib-bot\venv\lib\site-packages\urllib3\util\retry.py", line 592, in increment
    raise MaxRetryError(_pool, url, error or ResponseError(cause))
urllib3.exceptions.MaxRetryError: HTTPConnectionPool(host='example4567.com', port=80): Max retries exceeded with url: / (Caused by NewConnectionError('<urllib3.connection.HTTPConnection object at 0x00000211C9D68040>: Failed to establish a new connection: [Errno 11001] getaddrinfo failed'))

During handling of the above exception, another exception occurred:

Traceback (most recent call last):
  File "C:\Users\user\PycharmProjects\livelib-bot\livelib\webconnection.py", line 168, in get_page_text
    page = self._get_page(url)
  File "C:\Users\user\PycharmProjects\livelib-bot\livelib\webconnection.py", line 139, in _get_page
    result = requests.get(url, headers=headers)
  File "C:\Users\user\PycharmProjects\livelib-bot\venv\lib\site-packages\requests\api.py", line 73, in get
    return request("get", url, params=params, **kwargs)
  File "C:\Users\user\PycharmProjects\livelib-bot\venv\lib\site-packages\requests\api.py", line 59, in request
    return session.request(method=method, url=url, **kwargs)
  File "C:\Users\user\PycharmProjects\livelib-bot\venv\lib\site-packages\requests\sessions.py", line 587, in request
    resp = self.send(prep, **send_kwargs)
  File "C:\Users\user\PycharmProjects\livelib-bot\venv\lib\site-packages\requests\sessions.py", line 701, in send
    r = adapter.send(request, **kwargs)
  File "C:\Users\user\PycharmProjects\livelib-bot\venv\lib\site-packages\requests\adapters.py", line 565, in send
    raise ConnectionError(e, request=request)
requests.exceptions.ConnectionError: HTTPConnectionPool(host='example4567.com', port=80): Max retries exceeded with url: / (Caused by NewConnectionError('<urllib3.connection.HTTPConnection object at 0x00000211C9D68040>: Failed to establish a new connection: [Errno 11001] getaddrinfo failed'))
Can not get BS object from http://example4567.com
Traceback (most recent call last):
  File "C:\Users\user\PycharmProjects\livelib-bot\venv\lib\site-packages\urllib3\connection.py", line 174, in _new_conn
    conn = connection.create_connection(
  File "C:\Users\user\PycharmProjects\livelib-bot\venv\lib\site-packages\urllib3\util\connection.py", line 72, in create_connection
    for res in socket.getaddrinfo(host, port, family, socket.SOCK_STREAM):
  File "C:\Program Files\Python310\lib\socket.py", line 955, in getaddrinfo
    for res in _socket.getaddrinfo(host, port, family, type, proto, flags):
socket.gaierror: [Errno 11001] getaddrinfo failed

During handling of the above exception, another exception occurred:

Traceback (most recent call last):
  File "C:\Users\user\PycharmProjects\livelib-bot\venv\lib\site-packages\urllib3\connectionpool.py", line 703, in urlopen
    httplib_response = self._make_request(
  File "C:\Users\user\PycharmProjects\livelib-bot\venv\lib\site-packages\urllib3\connectionpool.py", line 398, in _make_request
    conn.request(method, url, **httplib_request_kw)
  File "C:\Users\user\PycharmProjects\livelib-bot\venv\lib\site-packages\urllib3\connection.py", line 244, in request
    super(HTTPConnection, self).request(method, url, body=body, headers=headers)
  File "C:\Program Files\Python310\lib\http\client.py", line 1282, in request
    self._send_request(method, url, body, headers, encode_chunked)
  File "C:\Program Files\Python310\lib\http\client.py", line 1328, in _send_request
    self.endheaders(body, encode_chunked=encode_chunked)
  File "C:\Program Files\Python310\lib\http\client.py", line 1277, in endheaders
    self._send_output(message_body, encode_chunked=encode_chunked)
  File "C:\Program Files\Python310\lib\http\client.py", line 1037, in _send_output
    self.send(msg)
  File "C:\Program Files\Python310\lib\http\client.py", line 975, in send
    self.connect()
  File "C:\Users\user\PycharmProjects\livelib-bot\venv\lib\site-packages\urllib3\connection.py", line 205, in connect
    conn = self._new_conn()
  File "C:\Users\user\PycharmProjects\livelib-bot\venv\lib\site-packages\urllib3\connection.py", line 186, in _new_conn
    raise NewConnectionError(
urllib3.exceptions.NewConnectionError: <urllib3.connection.HTTPConnection object at 0x00000211C9D68040>: Failed to establish a new connection: [Errno 11001] getaddrinfo failed

During handling of the above exception, another exception occurred:

Traceback (most recent call last):
  File "C:\Users\user\PycharmProjects\livelib-bot\venv\lib\site-packages\requests\adapters.py", line 489, in send
    resp = conn.urlopen(
  File "C:\Users\user\PycharmProjects\livelib-bot\venv\lib\site-packages\urllib3\connectionpool.py", line 787, in urlopen
    retries = retries.increment(
  File "C:\Users\user\PycharmProjects\livelib-bot\venv\lib\site-packages\urllib3\util\retry.py", line 592, in increment
    raise MaxRetryError(_pool, url, error or ResponseError(cause))
urllib3.exceptions.MaxRetryError: HTTPConnectionPool(host='example4567.com', port=80): Max retries exceeded with url: / (Caused by NewConnectionError('<urllib3.connection.HTTPConnection object at 0x00000211C9D68040>: Failed to establish a new connection: [Errno 11001] getaddrinfo failed'))

During handling of the above exception, another exception occurred:

Traceback (most recent call last):
  File "C:\Users\user\PycharmProjects\livelib-bot\livelib\webconnection.py", line 73, in get_page_bs
    result = bs4.BeautifulSoup(self.get_page_text(url), features='lxml')
  File "C:\Users\user\PycharmProjects\livelib-bot\livelib\webconnection.py", line 168, in get_page_text
    page = self._get_page(url)
  File "C:\Users\user\PycharmProjects\livelib-bot\livelib\webconnection.py", line 139, in _get_page
    result = requests.get(url, headers=headers)
  File "C:\Users\user\PycharmProjects\livelib-bot\venv\lib\site-packages\requests\api.py", line 73, in get
    return request("get", url, params=params, **kwargs)
  File "C:\Users\user\PycharmProjects\livelib-bot\venv\lib\site-packages\requests\api.py", line 59, in request
    return session.request(method=method, url=url, **kwargs)
  File "C:\Users\user\PycharmProjects\livelib-bot\venv\lib\site-packages\requests\sessions.py", line 587, in request
    resp = self.send(prep, **send_kwargs)
  File "C:\Users\user\PycharmProjects\livelib-bot\venv\lib\site-packages\requests\sessions.py", line 701, in send
    r = adapter.send(request, **kwargs)
  File "C:\Users\user\PycharmProjects\livelib-bot\venv\lib\site-packages\requests\adapters.py", line 565, in send
    raise ConnectionError(e, request=request)
requests.exceptions.ConnectionError: HTTPConnectionPool(host='example4567.com', port=80): Max retries exceeded with url: / (Caused by NewConnectionError('<urllib3.connection.HTTPConnection object at 0x00000211C9D68040>: Failed to establish a new connection: [Errno 11001] getaddrinfo failed'))
Making request to http://www.livelib.ru
Starting new HTTP connection (1): www.livelib.ru:80
http://www.livelib.ru:80 "GET / HTTP/1.1" 302 138
Starting new HTTPS connection (1): www.livelib.ru:443
https://www.livelib.ru:443 "GET / HTTP/1.1" 200 None
Making request to http://www.livelib.ru/jsndjsdnljdncldn/
Starting new HTTP connection (1): www.livelib.ru:80
http://www.livelib.ru:80 "GET /jsndjsdnljdncldn/ HTTP/1.1" 302 138
Starting new HTTPS connection (1): www.livelib.ru:443
https://www.livelib.ru:443 "GET /jsndjsdnljdncldn/ HTTP/1.1" 301 None
https://www.livelib.ru:443 "GET /jsndjsdnljdncldn HTTP/1.1" 404 None
Page at http://www.livelib.ru/jsndjsdnljdncldn/ is 404!
Making request to http://www.livelib.ru/reader/alkasnmklas
Starting new HTTP connection (1): www.livelib.ru:80
http://www.livelib.ru:80 "GET /reader/alkasnmklas HTTP/1.1" 302 138
Starting new HTTPS connection (1): www.livelib.ru:443
https://www.livelib.ru:443 "GET /reader/alkasnmklas HTTP/1.1" 404 None
Page at http://www.livelib.ru/reader/alkasnmklas is 404!
Making request to http://www.livelib.ru/reader/feana
Starting new HTTP connection (1): www.livelib.ru:80
http://www.livelib.ru:80 "GET /reader/feana HTTP/1.1" 302 138
Starting new HTTPS connection (1): www.livelib.ru:443
https://www.livelib.ru:443 "GET /reader/feana HTTP/1.1" 301 None
https://www.livelib.ru:443 "GET /reader/Feana HTTP/1.1" 200 None
Making request to http://www.google.com
Starting new HTTP connection (1): www.google.com:80
http://www.google.com:80 "GET / HTTP/1.1" 302 231
Starting new HTTPS connection (1): www.google.com:443
https://www.google.com:443 "GET /?gws_rd=ssl HTTP/1.1" 200 None
Making request to http://www.example.com
Starting new HTTP connection (1): www.example.com:80
http://www.example.com:80 "GET / HTTP/1.1" 200 648
Making request to http://example4567.com
Starting new HTTP connection (1): example4567.com:80
Can not open this page!
Traceback (most recent call last):
  File "C:\Users\user\PycharmProjects\livelib-bot\venv\lib\site-packages\urllib3\connection.py", line 174, in _new_conn
    conn = connection.create_connection(
  File "C:\Users\user\PycharmProjects\livelib-bot\venv\lib\site-packages\urllib3\util\connection.py", line 72, in create_connection
    for res in socket.getaddrinfo(host, port, family, socket.SOCK_STREAM):
  File "C:\Program Files\Python310\lib\socket.py", line 955, in getaddrinfo
    for res in _socket.getaddrinfo(host, port, family, type, proto, flags):
socket.gaierror: [Errno 11001] getaddrinfo failed

During handling of the above exception, another exception occurred:

Traceback (most recent call last):
  File "C:\Users\user\PycharmProjects\livelib-bot\venv\lib\site-packages\urllib3\connectionpool.py", line 703, in urlopen
    httplib_response = self._make_request(
  File "C:\Users\user\PycharmProjects\livelib-bot\venv\lib\site-packages\urllib3\connectionpool.py", line 398, in _make_request
    conn.request(method, url, **httplib_request_kw)
  File "C:\Users\user\PycharmProjects\livelib-bot\venv\lib\site-packages\urllib3\connection.py", line 244, in request
    super(HTTPConnection, self).request(method, url, body=body, headers=headers)
  File "C:\Program Files\Python310\lib\http\client.py", line 1282, in request
    self._send_request(method, url, body, headers, encode_chunked)
  File "C:\Program Files\Python310\lib\http\client.py", line 1328, in _send_request
    self.endheaders(body, encode_chunked=encode_chunked)
  File "C:\Program Files\Python310\lib\http\client.py", line 1277, in endheaders
    self._send_output(message_body, encode_chunked=encode_chunked)
  File "C:\Program Files\Python310\lib\http\client.py", line 1037, in _send_output
    self.send(msg)
  File "C:\Program Files\Python310\lib\http\client.py", line 975, in send
    self.connect()
  File "C:\Users\user\PycharmProjects\livelib-bot\venv\lib\site-packages\urllib3\connection.py", line 205, in connect
    conn = self._new_conn()
  File "C:\Users\user\PycharmProjects\livelib-bot\venv\lib\site-packages\urllib3\connection.py", line 186, in _new_conn
    raise NewConnectionError(
urllib3.exceptions.NewConnectionError: <urllib3.connection.HTTPConnection object at 0x00000211C9101BA0>: Failed to establish a new connection: [Errno 11001] getaddrinfo failed

During handling of the above exception, another exception occurred:

Traceback (most recent call last):
  File "C:\Users\user\PycharmProjects\livelib-bot\venv\lib\site-packages\requests\adapters.py", line 489, in send
    resp = conn.urlopen(
  File "C:\Users\user\PycharmProjects\livelib-bot\venv\lib\site-packages\urllib3\connectionpool.py", line 787, in urlopen
    retries = retries.increment(
  File "C:\Users\user\PycharmProjects\livelib-bot\venv\lib\site-packages\urllib3\util\retry.py", line 592, in increment
    raise MaxRetryError(_pool, url, error or ResponseError(cause))
urllib3.exceptions.MaxRetryError: HTTPConnectionPool(host='example4567.com', port=80): Max retries exceeded with url: / (Caused by NewConnectionError('<urllib3.connection.HTTPConnection object at 0x00000211C9101BA0>: Failed to establish a new connection: [Errno 11001] getaddrinfo failed'))

During handling of the above exception, another exception occurred:

Traceback (most recent call last):
  File "C:\Users\user\PycharmProjects\livelib-bot\livelib\webconnection.py", line 139, in _get_page
    result = requests.get(url, headers=headers)
  File "C:\Users\user\PycharmProjects\livelib-bot\venv\lib\site-packages\requests\api.py", line 73, in get
    return request("get", url, params=params, **kwargs)
  File "C:\Users\user\PycharmProjects\livelib-bot\venv\lib\site-packages\requests\api.py", line 59, in request
    return session.request(method=method, url=url, **kwargs)
  File "C:\Users\user\PycharmProjects\livelib-bot\venv\lib\site-packages\requests\sessions.py", line 587, in request
    resp = self.send(prep, **send_kwargs)
  File "C:\Users\user\PycharmProjects\livelib-bot\venv\lib\site-packages\requests\sessions.py", line 701, in send
    r = adapter.send(request, **kwargs)
  File "C:\Users\user\PycharmProjects\livelib-bot\venv\lib\site-packages\requests\adapters.py", line 565, in send
    raise ConnectionError(e, request=request)
requests.exceptions.ConnectionError: HTTPConnectionPool(host='example4567.com', port=80): Max retries exceeded with url: / (Caused by NewConnectionError('<urllib3.connection.HTTPConnection object at 0x00000211C9101BA0>: Failed to establish a new connection: [Errno 11001] getaddrinfo failed'))
Making request to http://www.livelib.ru
Starting new HTTP connection (1): www.livelib.ru:80
http://www.livelib.ru:80 "GET / HTTP/1.1" 302 138
Starting new HTTPS connection (1): www.livelib.ru:443
https://www.livelib.ru:443 "GET / HTTP/1.1" 200 None
Making request to http://www.yandex.com
Starting new HTTP connection (1): www.yandex.com:80
http://www.yandex.com:80 "GET / HTTP/1.1" 302 None
http://www.yandex.com:80 "GET /showcaptcha?cc=1&mt=5C5320E9B462F4737E543AA99837AE30CD7D621E109E0B66ED3BA41BC9371BF374792E3505AE27D5D354F2437A0AD6AE196021DB8B7FF07D31A4A9E2054406949B559D63D6393DA5189BCB972CF5F503E8A8FC8796DEC30CE9C6&retpath=aHR0cDovL3d3dy55YW5kZXguY29tLz8%2C_03325bfc427335a7d143da493e8c7883&t=2/1684924204/f41e661d443a6c73757704c71775f0f2&u=dd591de9-90eb139d-9df00034-4758985a&s=72b7038a0624524213e45fe86e022e61 HTTP/1.1" 200 13080
Making request to http://www.example.com
Starting new HTTP connection (1): www.example.com:80
http://www.example.com:80 "GET / HTTP/1.1" 200 648
Making request to http://example4567.com
Starting new HTTP connection (1): example4567.com:80
Can not open this page!
Traceback (most recent call last):
  File "C:\Users\user\PycharmProjects\livelib-bot\venv\lib\site-packages\urllib3\connection.py", line 174, in _new_conn
    conn = connection.create_connection(
  File "C:\Users\user\PycharmProjects\livelib-bot\venv\lib\site-packages\urllib3\util\connection.py", line 72, in create_connection
    for res in socket.getaddrinfo(host, port, family, socket.SOCK_STREAM):
  File "C:\Program Files\Python310\lib\socket.py", line 955, in getaddrinfo
    for res in _socket.getaddrinfo(host, port, family, type, proto, flags):
socket.gaierror: [Errno 11001] getaddrinfo failed

During handling of the above exception, another exception occurred:

Traceback (most recent call last):
  File "C:\Users\user\PycharmProjects\livelib-bot\venv\lib\site-packages\urllib3\connectionpool.py", line 703, in urlopen
    httplib_response = self._make_request(
  File "C:\Users\user\PycharmProjects\livelib-bot\venv\lib\site-packages\urllib3\connectionpool.py", line 398, in _make_request
    conn.request(method, url, **httplib_request_kw)
  File "C:\Users\user\PycharmProjects\livelib-bot\venv\lib\site-packages\urllib3\connection.py", line 244, in request
    super(HTTPConnection, self).request(method, url, body=body, headers=headers)
  File "C:\Program Files\Python310\lib\http\client.py", line 1282, in request
    self._send_request(method, url, body, headers, encode_chunked)
  File "C:\Program Files\Python310\lib\http\client.py", line 1328, in _send_request
    self.endheaders(body, encode_chunked=encode_chunked)
  File "C:\Program Files\Python310\lib\http\client.py", line 1277, in endheaders
    self._send_output(message_body, encode_chunked=encode_chunked)
  File "C:\Program Files\Python310\lib\http\client.py", line 1037, in _send_output
    self.send(msg)
  File "C:\Program Files\Python310\lib\http\client.py", line 975, in send
    self.connect()
  File "C:\Users\user\PycharmProjects\livelib-bot\venv\lib\site-packages\urllib3\connection.py", line 205, in connect
    conn = self._new_conn()
  File "C:\Users\user\PycharmProjects\livelib-bot\venv\lib\site-packages\urllib3\connection.py", line 186, in _new_conn
    raise NewConnectionError(
urllib3.exceptions.NewConnectionError: <urllib3.connection.HTTPConnection object at 0x00000211C91024D0>: Failed to establish a new connection: [Errno 11001] getaddrinfo failed

During handling of the above exception, another exception occurred:

Traceback (most recent call last):
  File "C:\Users\user\PycharmProjects\livelib-bot\venv\lib\site-packages\requests\adapters.py", line 489, in send
    resp = conn.urlopen(
  File "C:\Users\user\PycharmProjects\livelib-bot\venv\lib\site-packages\urllib3\connectionpool.py", line 787, in urlopen
    retries = retries.increment(
  File "C:\Users\user\PycharmProjects\livelib-bot\venv\lib\site-packages\urllib3\util\retry.py", line 592, in increment
    raise MaxRetryError(_pool, url, error or ResponseError(cause))
urllib3.exceptions.MaxRetryError: HTTPConnectionPool(host='example4567.com', port=80): Max retries exceeded with url: / (Caused by NewConnectionError('<urllib3.connection.HTTPConnection object at 0x00000211C91024D0>: Failed to establish a new connection: [Errno 11001] getaddrinfo failed'))

During handling of the above exception, another exception occurred:

Traceback (most recent call last):
  File "C:\Users\user\PycharmProjects\livelib-bot\livelib\webconnection.py", line 139, in _get_page
    result = requests.get(url, headers=headers)
  File "C:\Users\user\PycharmProjects\livelib-bot\venv\lib\site-packages\requests\api.py", line 73, in get
    return request("get", url, params=params, **kwargs)
  File "C:\Users\user\PycharmProjects\livelib-bot\venv\lib\site-packages\requests\api.py", line 59, in request
    return session.request(method=method, url=url, **kwargs)
  File "C:\Users\user\PycharmProjects\livelib-bot\venv\lib\site-packages\requests\sessions.py", line 587, in request
    resp = self.send(prep, **send_kwargs)
  File "C:\Users\user\PycharmProjects\livelib-bot\venv\lib\site-packages\requests\sessions.py", line 701, in send
    r = adapter.send(request, **kwargs)
  File "C:\Users\user\PycharmProjects\livelib-bot\venv\lib\site-packages\requests\adapters.py", line 565, in send
    raise ConnectionError(e, request=request)
requests.exceptions.ConnectionError: HTTPConnectionPool(host='example4567.com', port=80): Max retries exceeded with url: / (Caused by NewConnectionError('<urllib3.connection.HTTPConnection object at 0x00000211C91024D0>: Failed to establish a new connection: [Errno 11001] getaddrinfo failed'))
Can not get text from page! http://example4567.com
Traceback (most recent call last):
  File "C:\Users\user\PycharmProjects\livelib-bot\venv\lib\site-packages\urllib3\connection.py", line 174, in _new_conn
    conn = connection.create_connection(
  File "C:\Users\user\PycharmProjects\livelib-bot\venv\lib\site-packages\urllib3\util\connection.py", line 72, in create_connection
    for res in socket.getaddrinfo(host, port, family, socket.SOCK_STREAM):
  File "C:\Program Files\Python310\lib\socket.py", line 955, in getaddrinfo
    for res in _socket.getaddrinfo(host, port, family, type, proto, flags):
socket.gaierror: [Errno 11001] getaddrinfo failed

During handling of the above exception, another exception occurred:

Traceback (most recent call last):
  File "C:\Users\user\PycharmProjects\livelib-bot\venv\lib\site-packages\urllib3\connectionpool.py", line 703, in urlopen
    httplib_response = self._make_request(
  File "C:\Users\user\PycharmProjects\livelib-bot\venv\lib\site-packages\urllib3\connectionpool.py", line 398, in _make_request
    conn.request(method, url, **httplib_request_kw)
  File "C:\Users\user\PycharmProjects\livelib-bot\venv\lib\site-packages\urllib3\connection.py", line 244, in request
    super(HTTPConnection, self).request(method, url, body=body, headers=headers)
  File "C:\Program Files\Python310\lib\http\client.py", line 1282, in request
    self._send_request(method, url, body, headers, encode_chunked)
  File "C:\Program Files\Python310\lib\http\client.py", line 1328, in _send_request
    self.endheaders(body, encode_chunked=encode_chunked)
  File "C:\Program Files\Python310\lib\http\client.py", line 1277, in endheaders
    self._send_output(message_body, encode_chunked=encode_chunked)
  File "C:\Program Files\Python310\lib\http\client.py", line 1037, in _send_output
    self.send(msg)
  File "C:\Program Files\Python310\lib\http\client.py", line 975, in send
    self.connect()
  File "C:\Users\user\PycharmProjects\livelib-bot\venv\lib\site-packages\urllib3\connection.py", line 205, in connect
    conn = self._new_conn()
  File "C:\Users\user\PycharmProjects\livelib-bot\venv\lib\site-packages\urllib3\connection.py", line 186, in _new_conn
    raise NewConnectionError(
urllib3.exceptions.NewConnectionError: <urllib3.connection.HTTPConnection object at 0x00000211C91024D0>: Failed to establish a new connection: [Errno 11001] getaddrinfo failed

During handling of the above exception, another exception occurred:

Traceback (most recent call last):
  File "C:\Users\user\PycharmProjects\livelib-bot\venv\lib\site-packages\requests\adapters.py", line 489, in send
    resp = conn.urlopen(
  File "C:\Users\user\PycharmProjects\livelib-bot\venv\lib\site-packages\urllib3\connectionpool.py", line 787, in urlopen
    retries = retries.increment(
  File "C:\Users\user\PycharmProjects\livelib-bot\venv\lib\site-packages\urllib3\util\retry.py", line 592, in increment
    raise MaxRetryError(_pool, url, error or ResponseError(cause))
urllib3.exceptions.MaxRetryError: HTTPConnectionPool(host='example4567.com', port=80): Max retries exceeded with url: / (Caused by NewConnectionError('<urllib3.connection.HTTPConnection object at 0x00000211C91024D0>: Failed to establish a new connection: [Errno 11001] getaddrinfo failed'))

During handling of the above exception, another exception occurred:

Traceback (most recent call last):
  File "C:\Users\user\PycharmProjects\livelib-bot\livelib\webconnection.py", line 168, in get_page_text
    page = self._get_page(url)
  File "C:\Users\user\PycharmProjects\livelib-bot\livelib\webconnection.py", line 139, in _get_page
    result = requests.get(url, headers=headers)
  File "C:\Users\user\PycharmProjects\livelib-bot\venv\lib\site-packages\requests\api.py", line 73, in get
    return request("get", url, params=params, **kwargs)
  File "C:\Users\user\PycharmProjects\livelib-bot\venv\lib\site-packages\requests\api.py", line 59, in request
    return session.request(method=method, url=url, **kwargs)
  File "C:\Users\user\PycharmProjects\livelib-bot\venv\lib\site-packages\requests\sessions.py", line 587, in request
    resp = self.send(prep, **send_kwargs)
  File "C:\Users\user\PycharmProjects\livelib-bot\venv\lib\site-packages\requests\sessions.py", line 701, in send
    r = adapter.send(request, **kwargs)
  File "C:\Users\user\PycharmProjects\livelib-bot\venv\lib\site-packages\requests\adapters.py", line 565, in send
    raise ConnectionError(e, request=request)
requests.exceptions.ConnectionError: HTTPConnectionPool(host='example4567.com', port=80): Max retries exceeded with url: / (Caused by NewConnectionError('<urllib3.connection.HTTPConnection object at 0x00000211C91024D0>: Failed to establish a new connection: [Errno 11001] getaddrinfo failed'))
Making request to http://www.livelib.ru
Starting new HTTP connection (1): www.livelib.ru:80
http://www.livelib.ru:80 "GET / HTTP/1.1" 302 138
Starting new HTTPS connection (1): www.livelib.ru:443
https://www.livelib.ru:443 "GET / HTTP/1.1" 200 None
Making request to http://www.yandex.com
Starting new HTTP connection (1): www.yandex.com:80
http://www.yandex.com:80 "GET / HTTP/1.1" 302 None
http://www.yandex.com:80 "GET /showcaptcha?cc=1&mt=212DAD62E266DB9970CE7E2797A031823AEF4961144032BB35479D254C9D4AFAF559DD994F56903E94A583C55758491095732E9604219A60E6D05F4F43A3EC3C552041570D64A9CC237A07CEBAE9541BBC1C153D2EB5347AA27B&retpath=aHR0cDovL3d3dy55YW5kZXguY29tLz8%2C_03325bfc427335a7d143da493e8c7883&t=2/1684924204/d7a0b627e26b05624114c4028a721067&u=2c85c17f-b6c18300-43784481-f1b49aeb&s=8ee354c3319a4ac1f5bc60fafcd673d6 HTTP/1.1" 200 13084
Dir web_with_cache_test is found? False
Create dir web_with_cache_test
Dir web_with_cache_test/ is found? True
Create file <_io.TextIOWrapper name='web_with_cache_test/index.html' mode='x' encoding='utf-8'> 
Already have web_with_cache_test/index.html
Dir web_with_cache_test is found? True
Dir web_with_cache_test/foo is found? False
Create dir web_with_cache_test/foo
Dir web_with_cache_test/foo/ is found? True
Create file <_io.TextIOWrapper name='web_with_cache_test/foo/bar.html' mode='x' encoding='utf-8'> 
Already have web_with_cache_test/foo/bar.html
Already have web_with_cache_test/foo/bar.html
Dir web_with_cache_test is found? True
Dir web_with_cache_test/foo is found? True
Dir web_with_cache_test/foo/ is found? True
Create file <_io.TextIOWrapper name='web_with_cache_test/foo/2.html' mode='x' encoding='utf-8'> 
Already have web_with_cache_test/foo/2.html
Dir web_with_cache_test is found? True
Dir web_with_cache_test/foo is found? True
Dir web_with_cache_test/foo/bar is found? False
Create dir web_with_cache_test/foo/bar
Dir web_with_cache_test/foo/bar/ is found? True
Create file <_io.TextIOWrapper name='web_with_cache_test/foo/bar/index.html' mode='x' encoding='utf-8'> 
Already have web_with_cache_test/foo/bar/index.html
Dir web_with_cache_test is found? True
Dir web_with_cache_test/foo is found? True
Dir web_with_cache_test/foo/bar is found? True
Dir web_with_cache_test/foo/bar/ is found? True
Create file <_io.TextIOWrapper name='web_with_cache_test/foo/bar/1.html' mode='x' encoding='utf-8'> 
Already have web_with_cache_test/foo/bar/1.html
Dir web_with_cache_test is found? True
Dir web_with_cache_test/ is found? True
Create file <_io.TextIOWrapper name='web_with_cache_test/1.html' mode='x' encoding='utf-8'> 
Already have web_with_cache_test/1.html
Dir web_with_cache_test is found? True
Dir web_with_cache_test/foo is found? True
Dir web_with_cache_test/foo/ is found? True
Create file <_io.TextIOWrapper name='web_with_cache_test/foo/~12.html' mode='x' encoding='utf-8'> 
Already have web_with_cache_test/foo/~12.html
Cleaning dirs and files after testing
Cleaning dirs and files after testing
